Workbook

Sheet LQ
A1: Lapangan Usaha | B1: PDRB seri 2010 Menurut Lapangan Usaha (Juta Rupiah) | I1: LAJU PERTUMBUHAN | N1: RATA-RATA | O1: KONTRIBUSI % | T1: RATA-RATA
B2: Harga Konstan
B3: 2021 | C3: 2020 | D3: 2019 | E3: 2018 | F3: 2017 | G3: 2016 | H3: 2016 | I3: 2021 | J3: 2020 | K3: 2019 | L3: 2018 | M3: 2017 | O3: 2021 | P3: 2020 | Q3: 2019 | R3: 2018 | S3: 2017
A4: A. Pertanian, Kehutanan, dan Perikanan | B4: 116787.02 | C4: 116340.03 | D4: 115481.55 | E4: 109809.02 | F4: 108869.6 | G4: 106735.73 | H4: 106735.73 | I4: =M15 -> 0.045018846 | J4: =(C4-E4)/C4 -> 0.056137256 | K4: =(D4-F4)/D4 -> 0.057255466 | L4: =(E4-G4)/E4 -> 0.027987592 | M4: =(F4-H4)/F4 -> 0.019600237 | N4: =AVERAGE(I4:M4) -> 0.041199879 | O4: =B4/B$21 -> 0.017928908 | P4: =C4/C$21 -> 0.018431405 | Q4: =D4/D$21 -> 0.017847283 | R4: =E4/E$21 -> 0.017888218 | S4: =F4/F$21 -> 0.018704407 | T4: =SUM(O4:S4)/5 -> 0.018160044
A5: B. Pertambangan dan Penggalian | B5: 0 | C5: 0 | D5: 0 | E5: 0 | F5: 0 | G5: 0 | H5: 0 | I5: 0 | J5: 0 | K5: 0 | L5: 0 | M5: 0 | N5: =AVERAGE(I5:M5) -> 0 | O5: =B5/B$21 -> 0 | P5: =C5/C$21 -> 0 | Q5: =D5/D$21 -> 0 | R5: =E5/E$21 -> 0 | S5: =F5/F$21 -> 0 | T5: =SUM(O5:S5)/5 -> 0
A6: C. Industri Pengolahan | B6: 976664.1 | C6: 932910.91 | D6: 934870.61 | E6: 894350.14 | F6: 864272.22 | G6: 828143.74 | H6: 828143.74 | I6: =(B6-D6)/B6 -> 0.042792082 | J6: =(C6-E6)/C6 -> 0.041333818 | K6: =(D6-F6)/D6 -> 0.07551675 | L6: =(E6-G6)/E6 -> 0.074027383 | M6: =(F6-H6)/F6 -> 0.0418022 | N6: =AVERAGE(I6:M6) -> 0.055094446 | O6: =B6/B$21 -> 0.14993551 | P6: =C6/C$21 -> 0.1477983 | Q6: =D6/D$21 -> 0.14448109 | R6: =E6/E$21 -> 0.14569231 | S6: =F6/F$21 -> 0.14848681 | T6: =SUM(O6:S6)/5 -> 0.1472788
A7: D. Pengadaan Listrik dan Gas | B7: 24999.35 | C7: 22782.58 | D7: 22379.92 | E7: 21149.94 | F7: 19887.1 | G7: 19086.34 | H7: 19086.34 | I7: =(B7-D7)/B7 -> 0.10477992 | J7: =(C7-E7)/C7 -> 0.07166177 | K7: =(D7-F7)/D7 -> 0.11138646 | L7: =(E7-G7)/E7 -> 0.097570017 | M7: =(F7-H7)/F7 -> 0.040265298 | N7: =AVERAGE(I7:M7) -> 0.085132693 | O7: =B7/B$21 -> 0.0038378499 | P7: =C7/C$21 -> 0.0036093764 | Q7: =D7/D$21 -> 0.003458741 | R7: =E7/E$21 -> 0.0034453885 | S7: =F7/F$21 -> 0.0034167152 | T7: =SUM(O7:S7)/5 -> 0.0035536142
A8: E. Pengadaan Air, Pengelolaan Sampah, Limbah dan Daur Ulang | B8: 8891.03 | C8: 8872.97 | D8: 8914.87 | E8: 8569.3 | F8: 8228.4 | G8: 7868.22 | H8: 7868.22 | I8: =(B8-D8)/B8 -> -0.0026813541 | J8: =(C8-E8)/C8 -> 0.034224166 | K8: =(D8-F8)/D8 -> 0.077002805 | L8: =(E8-G8)/E8 -> 0.081812984 | M8: =(F8-H8)/F8 -> 0.043772787 | N8: =AVERAGE(I8:M8) -> 0.046826278 | O8: =B8/B$21 -> 0.001364933 | P8: =C8/C$21 -> 0.0014057182 | Q8: =D8/D$21 -> 0.001377763 | R8: =E8/E$21 -> 0.0013959646 | S8: =F8/F$21 -> 0.0014136852 | T8: =SUM(O8:S8)/5 -> 0.0013916128
A9: F. Konstruksi | B9: 1054427.4 | C9: 1021386.1 | D9: 1041119.1 | E9: 1000726.3 | F9: 952201.56 | G9: 907490.87 | H9: 907490.87 | I9: =(B9-D9)/B9 -> 0.0126214 | J9: =(C9-E9)/C9 -> 0.02022721 | K9: =(D9-F9)/D9 -> 0.085405716 | L9: =(E9-G9)/E9 -> 0.093167735 | M9: =(F9-H9)/F9 -> 0.046955069 | N9: =AVERAGE(I9:M9) -> 0.051675426 | O9: =B9/B$21 -> 0.16187358 | P9: =C9/C$21 -> 0.16181515 | Q9: =D9/D$21 -> 0.16090143 | R9: =E9/E$21 -> 0.1630213 | S9: =F9/F$21 -> 0.16359356 | T9: =SUM(O9:S9)/5 -> 0.16224101
A10: G. Perdagangan Besar dan Eceran; Reparasi Mobil dan Sepeda Motor | B10: 1010890.7 | C10: 959216.92 | D10: 994030.89 | E10: 941850.09 | F10: 889686.2 | G10: 844737.97 | H10: 844737.97 | I10: =(B10-D10)/B10 -> 0.016678134 | J10: =(C10-E10)/C10 -> 0.018105216 | K10: =(D10-F10)/D10 -> 0.10497128 | L10: =(E10-G10)/E10 -> 0.10310783 | M10: =(F10-H10)/F10 -> 0.050521442 | N10: =AVERAGE(I10:M10) -> 0.05867678 | O10: =B10/B$21 -> 0.1551899 | P10: =C10/C$21 -> 0.15196588 | Q10: =D10/D$21 -> 0.15362411 | R10: =E10/E$21 -> 0.1534302 | S10: =F10/F$21 -> 0.15285307 | T10: =SUM(O10:S10)/5 -> 0.15341263
A11: H. Transportasi dan Pergudangan | B11: 381908.37 | C11: 371393.25 | D11: 511366.87 | E11: 472092.23 | F11: 443250.98 | G11: 418762 | H11: 418762 | I11: =(B11-D11)/B11 -> -0.33897791 | J11: =(C11-E11)/C11 -> -0.27113842 | K11: =(D11-F11)/D11 -> 0.13320356 | L11: =(E11-G11)/E11 -> 0.1129657 | M11: =(F11-H11)/F11 -> 0.055248564 | N11: =AVERAGE(I11:M11) -> -0.0617397 | O11: =B11/B$21 -> 0.058629804 | P11: =C11/C$21 -> 0.058838728 | Q11: =D11/D$21 -> 0.07903002 | R11: =E11/E$21 -> 0.076905236 | S11: =F11/F$21 -> 0.076153001 | T11: =SUM(O11:S11)/5 -> 0.069911358
A12: I. Penyediaan Akomodasi dan Makan Minum | B12: 371237.65 | C12: 354869.82 | D12: 392225.82 | E12: 360973.97 | F12: 337687.35 | G12: 318041.12 | H12: 318041.12 | I12: =(B12-D12)/B12 -> -0.056535672 | J12: =(C12-E12)/C12 -> -0.017201096 | K12: =(D12-F12)/D12 -> 0.13904865 | L12: =(E12-G12)/E12 -> 0.11893614 | M12: =(F12-H12)/F12 -> 0.058178756 | N12: =AVERAGE(I12:M12) -> 0.048485355 | O12: =B12/B$21 -> 0.056991657 | P12: =C12/C$21 -> 0.05622097 | Q12: =D12/D$21 -> 0.060617174 | R12: =E12/E$21 -> 0.058803739 | S12: =F12/F$21 -> 0.058016578 | T12: =SUM(O12:S12)/5 -> 0.058130024
A13: J. Informasi dan Komunikasi | B13: 549524.44 | C13: 537630.7 | D13: 458256.15 | E13: 427612.45 | F13: 386751.83 | G13: 347340.64 | H13: 347340.64 | I13: =(B13-D13)/B13 -> 0.16608595 | J13: =(C13-E13)/C13 -> 0.20463536 | K13: =(D13-F13)/D13 -> 0.1560357 | L13: =(E13-G13)/E13 -> 0.18772094 | M13: =(F13-H13)/F13 -> 0.10190305 | N13: =AVERAGE(I13:M13) -> 0.1632762 | O13: =B13/B$21 -> 0.084361886 | P13: =C13/C$21 -> 0.085175232 | Q13: =D13/D$21 -> 0.070821938 | R13: =E13/E$21 -> 0.069659347 | S13: =F13/F$21 -> 0.066446131 | T13: =SUM(O13:S13)/5 -> 0.075292907
A14: K. Jasa Keuangan dan Asuransi | B14: 312431.71 | C14: 309950.91 | D14: 306268.29 | E14: 295081.77 | F14: 284960.96 | G14: 272244.6 | H14: 272244.6 | I14: =(B14-D14)/B14 -> 0.019727255 | J14: =(C14-E14)/C14 -> 0.047972564 | K14: =(D14-F14)/D14 -> 0.0695708 | L14: =(E14-G14)/E14 -> 0.077392683 | M14: =(F14-H14)/F14 -> 0.04462492 | N14: =AVERAGE(I14:M14) -> 0.051857645 | O14: =B14/B$21 -> 0.047963887 | P14: =C14/C$21 -> 0.0491046 | Q14: =D14/D$21 -> 0.047332729 | R14: =E14/E$21 -> 0.048069703 | S14: =F14/F$21 -> 0.048957889 | T14: =SUM(O14:S14)/5 -> 0.048285762
A15: L. Real Estate | B15: 228544.53 | C15: 223750.89 | D15: 224784.9 | E15: 217344.58 | F15: 206097.24 | G15: 196818.98 | H15: 196818.98 | I15: =(B15-D15)/B15 -> 0.016450317 | J15: =(C15-E15)/C15 -> 0.028631439 | K15: =(D15-F15)/D15 -> 0.083135744 | L15: =(E15-G15)/E15 -> 0.094438058 | M15: =(F15-H15)/F15 -> 0.045018846 | N15: =AVERAGE(I15:M15) -> 0.053534881 | O15: =B15/B$21 -> 0.035085696 | P15: =C15/C$21 -> 0.035448188 | Q15: =D15/D$21 -> 0.034739746 | R15: =E15/E$21 -> 0.035406082 | S15: =F15/F$21 -> 0.03540866 | T15: =SUM(O15:S15)/5 -> 0.035217674
A16: M,N . Jasa Perusahaan | B16: 23442.95 | C16: 23108.93 | D16: 24650.84 | E16: 22681.34 | F16: 20970.5 | G16: 19446.7 | H16: 19446.7 | I16: =(B16-D16)/B16 -> -0.051524659 | J16: =(C16-E16)/C16 -> 0.018503237 | K16: =(D16-F16)/D16 -> 0.14929877 | L16: =(E16-G16)/E16 -> 0.14261239 | M16: =(F16-H16)/F16 -> 0.07266398 | N16: =AVERAGE(I16:M16) -> 0.066310742 | O16: =B16/B$21 -> 0.0035989145 | P16: =C16/C$21 -> 0.003661079 | Q16: =D16/D$21 -> 0.003809704 | R16: =E16/E$21 -> 0.0036948581 | S16: =F16/F$21 -> 0.0036028494 | T16: =SUM(O16:S16)/5 -> 0.003673481
A17: O. Administrasi Pemerintahan, Pertahanan dan Jaminan Sosial Wajib | B17: 672846.92 | C17: 661857.19 | D17: 672482.41 | E17: 650260.5 | F17: 629054.75 | G17: 615023.35 | H17: 615023.35 | I17: =(B17-D17)/B17 -> 0.00054174284 | J17: =(C17-E17)/C17 -> 0.017521438 | K17: =(D17-F17)/D17 -> 0.064578135 | L17: =(E17-G17)/E17 -> 0.054189283 | M17: =(F17-H17)/F17 -> 0.022305531 | N17: =AVERAGE(I17:M17) -> 0.031827226 | O17: =B17/B$21 -> 0.1032941 | P17: =C17/C$21 -> 0.10485607 | Q17: =D17/D$21 -> 0.10392988 | R17: =E17/E$21 -> 0.10592938 | S17: =F17/F$21 -> 0.10807513 | T17: =SUM(O17:S17)/5 -> 0.10521691
... A20: R,S,T,U. Jasa Lainnya | B20: 139579.02 | C20: 138139.4 | D20: 148576.93 | E20: 136505.66 | F20: 124894.17 | G20: 114313.07 | H20: 114313.07 | I20: =(B20-D20)/B20 -> -0.064464631 | J20: =(C20-E20)/C20 -> 0.011826749 | K20: =(D20-F20)/D20 -> 0.15939729 | L20: =(E20-G20)/E20 -> 0.16257634 | M20: =(F20-H20)/F20 -> 0.084720528 | N20: =AVERAGE(I20:M20) -> 0.070811254 | O20: =B20/B$21 -> 0.02142789 | P20: =C20/C$21 -> 0.021885014 | Q20: =D20/D$21 -> 0.022962062 | R20: =E20/E$21 -> 0.02223718 | S20: =F20/F$21 -> 0.021457518 | T20: =SUM(O20:S20)/5 -> 0.021993933
A21: PRODUK DOMESTIK REGIONAL BRUTO | B21: 6513894.7 | C21: 6312054.4 | D21: 6470539.5 | E21: 6138622.8 | F21: 5820532 | G21: 5521525.5 | H21: 5521525.5 | O21: =B21/B$21 -> 1 | P21: =C21/C$21 -> 1 | Q21: =D21/D$21 -> 1 | R21: =E21/E$21 -> 1 | S21: =F21/F$21 -> 1 | T21: =SUM(O21:S21)/5 -> 1
A26: Lapangan Usaha | B26: LQ PDRB Kota Magelang | H26: Rata-Rata LQ
B28: 2021 | C28: 2020 | D28: 2019 | E28: 2018 | F28: 2017
A29: A. Pertanian, Kehutanan, dan Perikanan | B29: =(B4/$B$21)/(B51/$B$68) -> 0.14069893 | C29: =(C4/$C$21)/(C51/$C$68) -> 0.14106928 | D29: =(D4/$B$21)/(D51/$D$68) -> 0.14273726 | E29: =(E4/$E$21)/(E51/$E$68) -> 0.13849299 | F29: =(F4/$F$21)/(F51/$F$68) -> 0.14113166 | H29: =AVERAGE(B29:F29) -> 0.14082602 | J29: LQ<1 Sektor Non Potensial
A30: B. Pertambangan dan Penggalian | B30: =(B5/$B$21)/(B52/$B$68) -> 0 | C30: =(C5/$C$21)/(C52/$C$68) -> 0 | D30: =(D5/$B$21)/(D52/$D$68) -> 0 | E30: 0 | F30: 0 | H30: =AVERAGE(B30:F30) -> 0 | J30: LQ> Sektor Potensial
A31: C. Industri Pengolahan | B31: =(B6/$B$21)/(B53/$B$68) -> 0.44873845 | C31: =(C6/$C$21)/(C53/$C$68) -> 0.43811797 | D31: =(D6/$B$21)/(D53/$D$68) -> 0.42042574 | E31: =(E6/$E$21)/(E53/$E$68) -> 0.42561726 | F31: =(F6/$F$21)/(F53/$F$68) -> 0.42980223 | H31: =AVERAGE(B31:F31) -> 0.43254033
A32: D. Pengadaan Listrik dan Gas | B32: =(B7/$B$21)/(B54/$B$68) -> 3.2700702 | C32: =(C7/$C$21)/(C54/$C$68) -> 3.1536018 | D32: =(D7/$B$21)/(D54/$D$68) -> 3.1389111 | E32: =(E7/$E$21)/(E54/$E$68) -> 3.1512977 | F32: =(F7/$F$21)/(F54/$F$68) -> 3.1270096 | H32: =AVERAGE(B32:F32) -> 3.1681781
A33: E. Pengadaan Air, Pengelolaan Sampah, Limbah dan Daur Ulang | B33: =(B8/$B$21)/(B55/$B$68) -> 1.8276048 | C33: =(C8/$C$21)/(C55/$C$68) -> 1.9294534 | D33: =(D8/$B$21)/(D55/$D$68) -> 1.9737694 | E33: =(E8/$E$21)/(E55/$E$68) -> 1.9938822 | F33: =(F8/$F$21)/(F55/$F$68) -> 2.0112482 | H33: =AVERAGE(B33:F33) -> 1.9471916
A34: F. Konstruksi | B34: =(B9/$B$21)/(B56/$B$68) -> 1.5130466 | C34: =(C9/$C$21)/(C56/$C$68) -> 1.5716169 | D34: =(D9/$B$21)/(D56/$D$68) -> 1.5346798 | E34: =(E9/$E$21)/(E56/$E$68) -> 1.5592242 | F34: =(F9/$F$21)/(F56/$F$68) -> 1.5762032 | H34: =AVERAGE(B34:F34) -> 1.5509542
A35: G. Perdagangan Besar dan Eceran; Reparasi Mobil dan Sepeda Motor | B35: =(B10/$B$21)/(B57/$B$68) -> 1.0506709 | C35: =(C10/$C$21)/(C57/$C$68) -> 1.0534971 | D35: =(D10/$B$21)/(D57/$D$68) -> 1.0454459 | E35: =(E10/$E$21)/(E57/$E$68) -> 1.0571862 | F35: =(F10/$F$21)/(F57/$F$68) -> 1.0579166 | H35: =AVERAGE(B35:F35) -> 1.0529433
A36: H. Transportasi dan Pergudangan | B36: =(B11/$B$21)/(B58/$B$68) -> 2.4027414 | C36: =(C11/$C$21)/(C58/$C$68) -> 2.4100842 | D36: =(D11/$B$21)/(D58/$D$68) -> 2.2336065 | E36: =(E11/$E$21)/(E58/$E$68) -> 2.2531931 | F36: =(F11/$F$21)/(F58/$F$68) -> 2.278803 | H36: =AVERAGE(B36:F36) -> 2.3156856
A37: I. Penyediaan Akomodasi dan Makan Minum | B37: =(B12/$B$21)/(B59/$B$68) -> 1.7438299 | C37: =(C12/$C$21)/(C59/$C$68) -> 1.7633867 | D37: =(D12/$B$21)/(D59/$D$68) -> 1.7852533 | E37: =(E12/$E$21)/(E59/$E$68) -> 1.8049007 | F37: =(F12/$F$21)/(F59/$F$68) -> 1.8289982 | H37: =AVERAGE(B37:F37) -> 1.7852738
A38: J. Informasi dan Komunikasi | B38: =(B13/$B$21)/(B60/$B$68) -> 1.3507681 | C38: =(C13/$C$21)/(C60/$C$68) -> 1.399635 | D38: =(D13/$B$21)/(D60/$D$68) -> 1.3733951 | E38: =(E13/$E$21)/(E60/$E$68) -> 1.4407577 | F38: =(F13/$F$21)/(F60/$F$68) -> 1.4668522 | H38: =AVERAGE(B38:F38) -> 1.4062816
A39: K. Jasa Keuangan dan Asuransi | B39: =(B14/$B$21)/(B61/$B$68) -> 1.7366257 | C39: =(C14/$C$21)/(C61/$C$68) -> 1.7485737 | D39: =(D14/$B$21)/(D61/$D$68) -> 1.7570105 | E39: =(E14/$E$21)/(E61/$E$68) -> 1.7646579 | F39: =(F14/$F$21)/(F61/$F$68) -> 1.7679302 | H39: =AVERAGE(B39:F39) -> 1.7549596
A40: L. Real Estate | B40: =(B15/$B$21)/(B62/$B$68) -> 1.8288634 | C40: =(C15/$C$21)/(C62/$C$68) -> 1.8267441 | D40: =(D15/$B$21)/(D62/$D$68) -> 1.8216934 | E40: =(E15/$E$21)/(E62/$E$68) -> 1.8721926 | F40: =(F15/$F$21)/(F62/$F$68) -> 1.8773548 | H40: =AVERAGE(B40:F40) -> 1.8453696
A41: M,N . Jasa Perusahaan | B41: =(B16/$B$21)/(B63/$B$68) -> 0.94045489 | C41: =(C16/$C$21)/(C63/$C$68) -> 0.95432168 | D41: =(D16/$B$21)/(D63/$D$68) -> 0.94045363 | E41: =(E16/$E$21)/(E63/$E$68) -> 0.96340017 | F41: =(F16/$F$21)/(F63/$F$68) -> 0.97676197 | H41: =AVERAGE(B41:F41) -> 0.95507847
A42: O. Administrasi Pemerintahan, Pertahanan dan Jaminan Sosial Wajib | B42: =(B17/$B$21)/(B64/$B$68) -> 4.1999761 | C42: =(C17/$C$21)/(C64/$C$68) -> 4.0997139 | D42: =(D17/$B$21)/(D64/$D$68) -> 4.0890135 | E42: =(E17/$E$21)/(E64/$E$68) -> 4.1299937 | F42: =(F17/$F$21)/(F64/$F$68) -> 4.1447799 | H42: =AVERAGE(B42:F42) -> 4.1326954
... A45: R,S,T,U. Jasa Lainnya | B45: =(B20/$B$21)/(B67/$B$68) -> 1.3299878 | C45: =(C20/$C$21)/(C67/$C$68) -> 1.3215506 | D45: =(D20/$B$21)/(D67/$D$68) -> 1.3015756 | E45: =(E20/$E$21)/(E67/$E$68) -> 1.3130822 | F45: =(F20/$F$21)/(F67/$F$68) -> 1.3169809 | H45: =AVERAGE(B45:F45) -> 1.3166354
A48: Sektor PDRB Lapangan Usaha Seri 2010 | B48: [Seri 2010] PDRB Triwulanan seri 2010 Provinsi Jawa Tengah Menurut Lapangan Usaha (Juta Rupiah) | I48: LAJU PERTUMBUHAN | N48: RATA-RATA | O48: KONTRIBUSI % | T48: RATA-RATA
B50: 2021 | C50: 2020 | D50: 2019 | E50: 2018 | F50: 2017 | H50: 2016 | I50: 2021 | J50: 2020 | K50: 2019 | L50: 2018 | M50: 2017 | O50: 2021 | P50: 2020 | Q50: 2019 | R50: 2018 | S50: 2017
A51: A. Pertanian, Kehutanan, dan Perikanan | B51: 1.2708915e+08 | C51: 1.2611176e+08 | D51: 1.2315002e+08 | E51: 1.2155448e+08 | F51: 1.1845017e+08 | H51: 1.1633112e+08 | I51: =(B51-D51)/B51 -> 0.030995019 | J51: =(C51-E51)/C51 -> 0.036136835 | K51: =(D51-F51)/D51 -> 0.038163613 | L51: =(E51-G51)/E51 -> 1 | M51: =(F51-H51)/F51 -> 0.017889846 | N51: =SUM(I51:M51)/5 -> 0.22463706 | O51: =B51/B$68 -> 0.12742747 | P51: =C51/C$68 -> 0.13065499 | Q51: =D51/D$68 -> 0.1242037 | R51: =E51/E$68 -> 0.12916334 | S51: =F51/F$68 -> 0.13253162 | T51: =SUM(O51:S51)/5 -> 0.12879622
A52: B. Pertambangan dan Penggalian | B52: 22326160 | C52: 21385268 | D52: 21557115 | E52: 20855982 | F52: 20356483 | H52: 19367597 | I52: =(B52-D52)/B52 -> 0.034445906 | J52: =(C52-E52)/C52 -> 0.024750011 | K52: =(D52-F52)/D52 -> 0.055695399 | L52: =(E52-G52)/E52 -> 1 | M52: =(F52-H52)/F52 -> 0.048578426 | N52: =SUM(I52:M52)/5 -> 0.23269395 | O52: =B52/B$68 -> 0.022385593 | P52: =C52/C$68 -> 0.022155681 | Q52: =D52/D$68 -> 0.021741559 | R52: =E52/E$68 -> 0.02216149 | S52: =F52/F$68 -> 0.022776477 | T52: =SUM(O52:S52)/5 -> 0.02224416
...

Sheet KLASSEN
A1: Lapangan Usaha | B1: Pertumbuhan PDRB (Persen) KOTA MAGELANG | G1: Rata-Rata | H1: Distribusi PDRB (Persen) | M1: Rata-Rata | O1: Lapangan Usaha | Q1: Laju Pertumbuhan JAWA TENGAH | V1: Rata-rata Pertumbuhan | W1: Distribusi Kontribusi | AB1: Rata-rata Kontribusi
B2: 2017 | C2: 2018 | D2: 2019 | E2: 2020 | F2: 2021 | H2: 2017 | I2: 2018 | J2: 2019 | K2: 2020 | L2: 2021 | Q2: 2017 | R2: 2018 | S2: 2019 | T2: 2020 | U2: 2021 | W2: 2017 | X2: 2018 | Y2: 2019 | Z2: 2020 | AA2: 2021
A3: A. Pertanian, Kehutanan, dan Perikanan | B3: 2 | C3: 0.86 | D3: 5.17 | E3: 0.74 | F3: 0.38 | G3: =AVERAGE(B3:F3) -> 1.83 | H3: 1.86 | I3: 1.8 | J3: 1.81 | K3: 1.86 | L3: 1.81 | M3: =AVERAGE(H3:L3) -> 1.828 | O3: A | P3: Pertanian, Kehutanan, dan Perikanan | Q3: 1.8215723 | R3: 2.6207699 | S3: 1.3126158 | T3: 2.4049826 | U3: 0.7750222 | V3: =AVERAGE(Q3:U3) -> 1.7869925 | W3: 13.253162 | X3: 12.916334 | Y3: 12.42037 | Z3: 13.065499 | AA3: 12.742747 | AB3: =AVERAGE(W3:AA3) -> 12.879622
A4: B. Pertambangan dan Penggalian | B4: - | C4: - | D4: - | E4: - | F4: - | H4: - | I4: - | J4: - | K4: - | L4: - | O4: B | P4: Pertambangan dan Penggalian | Q4: 5.1058782 | R4: 2.4537577 | S4: 3.3617854 | T4: -0.79717415 | U4: 4.3997232 | V4: =AVERAGE(Q4:U4) -> 2.9047941 | W4: 2.2776477 | X4: 2.216149 | Y4: 2.1741559 | Z4: 2.2155681 | AA4: 2.2385593 | AB4: =AVERAGE(W4:AA4) -> 2.224416
A5: C. Industri Pengolahan | B5: 4.36 | C5: 3.48 | D5: 4.53 | E5: -0.21 | F5: 4.69 | G5: =AVERAGE(B5:F5) -> 3.37 | H5: 16.06 | I5: 15.82 | J5: 15.62 | K5: 16.13 | L5: 16.6 | M5: =AVERAGE(H5:L5) -> 16.046 | O5: C | P5: Industri Pengolahan | Q5: 4.3280677 | R5: 4.3310735 | S5: 5.0684576 | T5: -3.7974651 | U5: 2.3407708 | V5: =AVERAGE(Q5:U5) -> 2.4541809 | W5: 34.547706 | X5: 34.230828 | Y5: 34.136695 | Z5: 33.734818 | AA5: 33.412672 | AB5: =AVERAGE(W5:AA5) -> 34.012544
A6: D. Pengadaan Listrik dan Gas | B6: 4.2 | C6: 6.35 | D6: 5.82 | E6: 1.8 | F6: 9.73 | G6: =AVERAGE(B6:F6) -> 5.58 | H6: 0.29 | I6: 0.3 | J6: 0.29 | K6: 0.3 | L6: 0.31 | M6: =AVERAGE(H6:L6) -> 0.298 | O6: D | P6: Pengadaan Listrik dan Gas | Q6: 5.2199603 | R6: 5.3621644 | S6: 5.4771305 | T6: 1.7925859 | U6: 5.9549989 | V6: =AVERAGE(Q6:U6) -> 4.761368 | W6: 0.10926462 | X6: 0.10933237 | Y6: 0.1094558 | Z6: 0.11445251 | AA6: 0.11736292 | AB6: =AVERAGE(W6:AA6) -> 0.11197364
A7: E. Pengadaan Air, Pengelolaan Sampah, Limbah dan Daur Ulang | B7: 4.58 | C7: 4.14 | D7: 4.03 | E7: -0.47 | F7: 0.2 | G7: =AVERAGE(B7:F7) -> 2.496 | H7: 0.12 | I7: 0.12 | J7: 0.12 | K7: 0.13 | L7: 0.12 | M7: =AVERAGE(H7:L7) -> 0.122 | O7: E | P7: Pengadaan Air, Pengelolaan Sampah, Limbah dan Daur Ulang | Q7: 6.5110376 | R7: 4.8825781 | S7: 4.3449069 | T7: 2.2858886 | U7: 5.920721 | V7: =AVERAGE(Q7:U7) -> 4.7890264 | W7: 0.070288947 | X7: 0.07001239 | Y7: 0.069339049 | Z7: 0.072855775 | AA7: 0.074684256 | AB7: =AVERAGE(W7:AA7) -> 0.071436083
A8: F. Konstruksi | B8: 4.93 | C8: 5.1 | D8: 4.04 | E8: -1.9 | F8: 3.23 | G8: =AVERAGE(B8:F8) -> 3.08 | H8: 16.51 | I8: 16.79 | J8: 16.76 | K8: 16.68 | L8: 16.86 | M8: =AVERAGE(H8:L8) -> 16.72 | O8: F | P8: Konstruksi | Q8: 7.1290993 | R8: 6.0711516 | S8: 4.9480557 | T8: -3.7589804 | U8: 7.3660551 | V8: =AVERAGE(Q8:U8) -> 4.3510763 | W8: 10.378964 | X8: 10.455283 | Y8: 10.414583 | Z8: 10.296094 | AA8: 10.698519 | AB8: =AVERAGE(W8:AA8) -> 10.448689
A9: G. Perdagangan Besar dan Eceran; Reparasi Mobil dan Sepeda Motor | B9: 5.32 | C9: 5.86 | D9: 5.54 | E9: -3.5 | F9: 5.39 | G9: =AVERAGE(B9:F9) -> 3.722 | H9: 14.29 | I9: 14.4 | J9: 14.51 | K9: 14.31 | L9: 14.53 | M9: =AVERAGE(H9:L9) -> 14.408 | O9: G | P9: Perdagangan Besar dan Eceran; Reparasi Mobil dan Sepeda Motor | Q9: 5.8724708 | R9: 5.7674652 | S9: 5.9659953 | T9: -3.7978505 | U9: 5.803457 | V9: =AVERAGE(Q9:U9) -> 3.9223076 | W9: 14.448499 | X9: 14.513072 | Y9: 14.596798 | Z9: 14.424898 | AA9: 14.770553 | AB9: =AVERAGE(W9:AA9) -> 14.550764
A10: H. Transportasi dan Pergudangan | B10: 5.85 | C10: 6.51 | D10: 8.32 | E10: -27.37 | F10: 2.83 | G10: =AVERAGE(B10:F10) -> -0.772 | H10: 6.69 | I10: 6.66 | J10: 6.84 | K10: 5.2 | L10: 5.24 | M10: =AVERAGE(H10:L10) -> 6.126 | O10: H | P10: Transportasi dan Pergudangan | Q10: 6.3005185 | R10: 7.5456228 | S10: 8.4915646 | T10: -32.379951 | U10: 3.2752381 | V10: =AVERAGE(Q10:U10) -> -1.3534013 | W10: 3.3417984 | X10: 3.4131667 | Y10: 3.5146752 | Z10: 2.4413557 | AA10: 2.4401213 | AB10: =AVERAGE(W10:AA10) -> 3.0302234
A11: I. Penyediaan Akomodasi dan Makan Minum | B11: 6.18 | C11: 6.9 | D11: 8.66 | E11: -9.52 | F11: 4.61 | G11: =AVERAGE(B11:F11) -> 3.366 | H11: 5.92 | I11: 5.93 | J11: 6.07 | K11: 5.58 | L11: 5.64 | M11: =AVERAGE(H11:L11) -> 5.828 | O11: I | P11: Penyediaan Akomodasi dan Makan Minum | Q11: 6.4454776 | R11: 8.1504378 | S11: 9.0717436 | T11: -7.9794597 | U11: 5.9186053 | V11: =AVERAGE(Q11:U11) -> 4.3213609 | W11: 3.1720413 | X11: 3.2580041 | Y11: 3.3728389 | Z11: 3.1882382 | AA11: 3.268189 | AB11: =AVERAGE(W11:AA11) -> 3.2518623
A12: J. Informasi dan Komunikasi | B12: 11.35 | C12: 10.57 | D12: 7.17 | E12: 17.32 | F12: 2.21 | G12: =AVERAGE(B12:F12) -> 9.724 | H12: 5.12 | I12: 5.25 | J12: 5.3 | K12: 6.29 | L12: 6.2 | M12: =AVERAGE(H12:L12) -> 5.632 | O12: J | P12: Informasi dan Komunikasi | Q12: 13.269745 | R12: 12.388171 | S12: 11.622542 | T12: 15.652779 | U12: 6.0431926 | V12: =AVERAGE(Q12:U12) -> 11.795286 | W12: 4.5298449 | X12: 4.8349106 | Y12: 5.1223833 | Z12: 6.0855317 | AA12: 6.245475 | AB12: =AVERAGE(W12:AA12) -> 5.3636291
A13: K. Jasa Keuangan dan Asuransi | B13: 4.67 | C13: 3.55 | D13: 3.79 | E13: 1.2 | F13: 0.8 | G13: =AVERAGE(B13:F13) -> 2.802 | H13: 5.19 | I13: 5.15 | J13: 5.06 | K13: 5.19 | L13: 5.17 | M13: =AVERAGE(H13:L13) -> 5.152 | O13: K | P13: Jasa Keuangan dan Asuransi | Q13: 5.1692839 | R13: 3.5783084 | S13: 3.5009444 | T13: 2.160009 | U13: 1.6215385 | V13: =AVERAGE(Q13:U13) -> 3.2060168 | W13: 2.7692207 | X13: 2.7240238 | Y13: 2.6760051 | Z13: 2.808266 | AA13: 2.7619013 | AB13: =AVERAGE(W13:AA13) -> 2.7478834
A14: L. Real Estate | B14: 4.71 | C14: 5.46 | D14: 3.42 | E14: -0.46 | F14: 2.14 | G14: =AVERAGE(B14:F14) -> 3.054 | H14: 3.18 | I14: 3.2 | J14: 3.13 | K14: 3.17 | L14: 3.1 | M14: =AVERAGE(H14:L14) -> 3.156 | O14: L | P14: Real Estate | Q14: 6.4775084 | R14: 5.5795255 | S14: 5.5339149 | T14: -0.27711767 | U14: 2.152349 | V14: =AVERAGE(Q14:U14) -> 3.893236 | W14: 1.8860932 | X14: 1.891156 | Y14: 1.8943103 | Z14: 1.940512 | AA14: 1.9184427 | AB14: =AVERAGE(W14:AA14) -> 1.9061028
A15: M,N . Jasa Perusahaan | B15: 7.84 | C15: 8.16 | D15: 8.68 | E15: -6.25 | F15: 1.45 | G15: =AVERAGE(B15:F15) -> 3.976 | H15: 0.36 | I15: 0.37 | J15: 0.39 | K15: 0.38 | L15: 0.37 | M15: =AVERAGE(H15:L15) -> 0.374 | O15: M,N | P15: Jasa Perusahaan | Q15: 8.7169019 | R15: 9.4836259 | S15: 10.542896 | T15: -7.1909506 | U15: 3.0706711 | V15: =AVERAGE(Q15:U15) -> 4.9246289 | W15: 0.36885643 | X15: 0.38352267 | Y15: 0.40239595 | Z15: 0.38363155 | AA15: 0.38267806 | AB15: =AVERAGE(W15:AA15) -> 0.38421693
A16: O. Administrasi Pemerintahan, Pertahanan dan Jaminan Sosial Wajib | B16: 2.28 | C16: 3.37 | D16: 3.42 | E16: -1.58 | F16: 1.66 | G16: =AVERAGE(B16:F16) -> 1.83 | H16: 11.74 | I16: 11.38 | J16: 11.11 | K16: 11.22 | L16: 10.87 | M16: =AVERAGE(H16:L16) -> 11.264 | O16: O | P16: Administrasi Pemerintahan, Pertahanan dan Jaminan Sosial Wajib | Q16: 2.5707847 | R16: 3.5757865 | S16: 3.7105383 | T16: -1.3838651 | U16: -0.64160678 | V16: =AVERAGE(Q16:U16) -> 1.5663275 | W16: 2.6074998 | X16: 2.5648799 | Y16: 2.524769 | Z16: 2.5576435 | AA16: 2.4593974 | AB16: =AVERAGE(W16:AA16) -> 2.5428379
... A19: R,S,T,U. Jasa Lainnya | B19: 9.26 | C19: 9.3 | D19: 8.84 | E19: -7.03 | F19: 1.04 | G19: =AVERAGE(B19:F19) -> 4.282 | H19: 2.06 | I19: 2.1 | J19: 2.15 | K19: 2.04 | L19: 1.97 | M19: =AVERAGE(H19:L19) -> 2.064 | O19: R,S,T,U | P19: Jasa Lainnya | Q19: 8.976619 | R19: 9.4468501 | S19: 9.0239104 | T19: -8.0077207 | U19: 0.52743484 | V19: =AVERAGE(Q19:U19) -> 3.9934187 | W19: 1.6292961 | X19: 1.6935101 | Y19: 1.7524323 | Z19: 1.6560103 | AA19: 1.6111344 | AB19: =AVERAGE(W19:AA19) -> 1.6684766
O20: TOTAL | Q20: 5.2586239 | R20: 5.2968763 | S20: 5.3581845 | T20: -2.6514206 | U20: 3.327484 | V20: =AVERAGE(Q20:U20) -> 3.3179496 | W20: 100 | X20: 100 | Y20: 100 | Z20: 100 | AA20: 100 | AB20: =AVERAGE(W20:AA20) -> 100
A22: Lapangan Usaha | B22: Prov. Jawa Tengah | D22: Kota Magelang | F22: Keterangan | G22: Kuadran
B23: Rata-Rata Pertumbuhan (%) (g) | C23: Rata-Rata Kontribusi (%) (s) | D23: Rata-Rata Pertumbuhan (%) (gi) | E23: Rata-Rata Kontribusi (%) (si)
A25: A. Pertanian, Kehutanan, dan Perikanan | B25: 1.7869925 | C25: 12.879622 | D25: 1.83 | E25: 1.828 | G25: 3
A26: B. Pertambangan dan Penggalian | B26: 2.9047941 | C26: 2.224416 | G26: 4
A27: C. Industri Pengolahan | B27: 2.4541809 | C27: 34.012544 | D27: 3.37 | E27: 16.046 | G27: 3
A28: D. Pengadaan Listrik, Gas | B28: 4.761368 | C28: 0.11197364 | D28: 5.58 | E28: 0.298 | G28: 2
A29: E. Pengadaan Air | B29: 4.7890264 | C29: 0.071436083 | D29: 2.496 | E29: 0.122 | G29: 2
A30: F. Konstruksi | B30: 4.3510763 | C30: 10.448689 | D30: 3.08 | E30: 16.72 | G30: 2
A31: G. Perdagangan Besar dan Eceran, dan Reparasi Mobil dan Sepeda Motor | B31: 3.9223076 | C31: 14.550764 | D31: 3.722 | E31: 14.408 | G31: 4
A32: H. Transportasi dan Pergudangan | B32: -1.3534013 | C32: 3.0302234 | D32: -0.772 | E32: 6.126 | G32: 2
A33: I. Penyediaan Akomodasi dan Makan Minum | B33: 4.3213609 | C33: 3.2518623 | D33: 3.366 | E33: 5.828 | G33: 2
A34: J. Informasi dan Komunikasi | B34: 11.795286 | C34: 5.3636291 | D34: 9.724 | E34: 5.632 | G34: 2
A35: K. Jasa Keuangan | B35: 3.2060168 | C35: 2.7478834 | D35: 2.802 | E35: 5.152 | G35: 2
A36: L. Real Estate | B36: 3.893236 | C36: 1.9061028 | D36: 3.054 | E36: 3.156 | G36: 2
A37: M,N. Jasa Perusahaan | B37: 4.9246289 | C37: 0.38421693 | D37: 3.976 | E37: 0.374 | G37: 4
A38: O. Administrasi Pemerintahan, Pertahanan dan Jaminan Sosial Wajib | B38: 1.5663275 | C38: 2.5428379 | D38: 1.83 | E38: 11.264 | G38: 1
... A41: R,S,T,U. Jasa lainnya | B41: 3.9934187 | C41: 1.6684766 | D41: 4.282 | E41: 2.064 | G41: 1
C48: Kontribusi Sektoral | D48: Pertumbuhan Sektoral
D49: gi>=g | E49: gi<g
C51: si>=s | D51: KUADRAN I Sektor maju dan tumbuh pesat (rapid growth sector) | E51: KUADRAN II Sektor maju tetapi tertekan (retearted sector)
C52: si<s | D52: KUADRAN III Sektor potensial atau masih dapat berkembang dengan pesat | E52: KUADRAN IV Sektor relatif tertinggal (relative backward sector)

Sheet RASIO INVESTASI
A1: Lapangan Usaha | B1: Distribusi PDRB (Persen) | H1: Rata-Rata | I1: Nilai Investasi (Rasio) | O1: Pertumbuhan PDRB (Persen) KOTA MAGELANG | T1: Rata-Rata
B2: 2016 | C2: 2017 | D2: 2018 | E2: 2019 | F2: 2020 | G2: 2021 | I2: 2016 | J2: 2017 | K2: 2018 | L2: 2019 | M2: 2020 | N2: 2021 | O2: 2017 | P2: 2018 | Q2: 2019 | R2: 2020 | S2: 2021
A3: A. Pertanian, Kehutanan, dan Perikanan | B3: 1.94 | C3: 1.86 | D3: 1.8 | E3: 1.81 | F3: 1.86 | G3: 1.81 | H3: =AVERAGE(B3:G3) -> 1.8466667 | I3: =B3*$B$20/100 -> 49966.601 | J3: =C3*$C$20/100 -> 50563.102 | K3: =D3*$D$20/100 -> 52580.042 | L3: =E3*$E$20/100 -> 55296.238 | M3: =F3*$F$20/100 -> 53774.605 | N3: =G3*$G$20 -> 8454646.6 | O3: 2 | P3: 0.86 | Q3: 5.17 | R3: 0.74 | S3: 0.38 | T3: 1.83
A4: B. Pertambangan dan Penggalian | I4: =B4*$B$20/100 -> 0 | J4: =C4*$C$20/100 -> 0 | K4: =D4*$D$20/100 -> 0 | L4: =E4*$E$20/100 -> 0 | M4: =F4*$F$20/100 -> 0 | N4: =G4*$G$20 -> 0 | O4: - | P4: - | Q4: - | R4: - | S4: -
A5: C. Industri Pengolahan | B5: 16.18 | C5: 16.06 | D5: 15.82 | E5: 15.62 | F5: 16.13 | G5: 16.6 | H5: =AVERAGE(B5:G5) -> 16.068333 | I5: =B5*$B$20/100 -> 416731.76 | J5: =C5*$C$20/100 -> 436582.48 | K5: =D5*$D$20/100 -> 462120.15 | L5: =E5*$E$20/100 -> 477197.37 | M5: =F5*$F$20/100 -> 466335.69 | N5: =G5*$G$20 -> 77539853 | O5: 4.36 | P5: 3.48 | Q5: 4.53 | R5: -0.21 | S5: 4.69 | T5: 3.37
A6: D. Pengadaan Listrik dan Gas | B6: 0.28 | C6: 0.29 | D6: 0.3 | E6: 0.29 | F6: 0.3 | G6: 0.31 | H6: =AVERAGE(B6:G6) -> 0.295 | I6: =B6*$B$20/100 -> 7211.6744 | J6: =C6*$C$20/100 -> 7883.4944 | K6: =D6*$D$20/100 -> 8763.3403 | L6: =E6*$E$20/100 -> 8859.6182 | M6: =F6*$F$20/100 -> 8673.3235 | N6: =G6*$G$20 -> 1448033.4 | O6: 4.2 | P6: 6.35 | Q6: 5.82 | R6: 1.8 | S6: 9.73 | T6: 5.58
A7: E. Pengadaan Air, Pengelolaan Sampah, Limbah dan Daur Ulang | B7: 0.13 | C7: 0.12 | D7: 0.12 | E7: 0.12 | F7: 0.13 | G7: 0.12 | H7: =AVERAGE(B7:G7) -> 0.12333333 | I7: =B7*$B$20/100 -> 3348.2774 | J7: =C7*$C$20/100 -> 3262.1356 | K7: =D7*$D$20/100 -> 3505.3361 | L7: =E7*$E$20/100 -> 3666.0489 | M7: =F7*$F$20/100 -> 3758.4402 | N7: =G7*$G$20 -> 560529.06 | O7: 4.58 | P7: 4.14 | Q7: 4.03 | R7: -0.47 | S7: 0.2 | T7: 2.496
A8: F. Konstruksi | B8: 16.56 | C8: 16.51 | D8: 16.79 | E8: 16.76 | F8: 16.68 | G8: 16.86 | H8: =AVERAGE(B8:G8) -> 16.693333 | I8: =B8*$B$20/100 -> 426519.03 | J8: =C8*$C$20/100 -> 448815.49 | K8: =D8*$D$20/100 -> 490454.95 | L8: =E8*$E$20/100 -> 512024.83 | M8: =F8*$F$20/100 -> 482236.78 | N8: =G8*$G$20 -> 78754332 | O8: 4.93 | P8: 5.1 | Q8: 4.04 | R8: -1.9 | S8: 3.23 | T8: 3.08
A9: G. Perdagangan Besar dan Eceran; Reparasi Mobil dan Sepeda Motor | B9: 14.35 | C9: 14.29 | D9: 14.4 | E9: 14.51 | F9: 14.31 | G9: 14.53 | H9: =AVERAGE(B9:G9) -> 14.398333 | I9: =B9*$B$20/100 -> 369598.31 | J9: =C9*$C$20/100 -> 388465.98 | K9: =D9*$D$20/100 -> 420640.34 | L9: =E9*$E$20/100 -> 443286.42 | M9: =F9*$F$20/100 -> 413717.53 | N9: =G9*$G$20 -> 67870727 | O9: 5.32 | P9: 5.86 | Q9: 5.54 | R9: -3.5 | S9: 5.39 | T9: 3.722
A10: H. Transportasi dan Pergudangan | B10: 6.75 | C10: 6.69 | D10: 6.66 | E10: 6.84 | F10: 5.2 | G10: 5.24 | H10: =AVERAGE(B10:G10) -> 6.23 | I10: =B10*$B$20/100 -> 173852.86 | J10: =C10*$C$20/100 -> 181864.06 | K10: =D10*$D$20/100 -> 194546.16 | L10: =E10*$E$20/100 -> 208964.79 | M10: =F10*$F$20/100 -> 150337.61 | N10: =G10*$G$20 -> 24476435 | O10: 5.85 | P10: 6.51 | Q10: 8.32 | R10: -27.37 | S10: 2.83 | T10: -0.772
A11: I. Penyediaan Akomodasi dan Makan Minum | B11: 5.98 | C11: 5.92 | D11: 5.93 | E11: 6.07 | F11: 5.58 | G11: 5.64 | H11: =AVERAGE(B11:G11) -> 5.8533333 | I11: =B11*$B$20/100 -> 154020.76 | J11: =C11*$C$20/100 -> 160932.02 | K11: =D11*$D$20/100 -> 173222.03 | L11: =E11*$E$20/100 -> 185440.97 | M11: =F11*$F$20/100 -> 161323.82 | N11: =G11*$G$20 -> 26344866 | O11: 6.18 | P11: 6.9 | Q11: 8.66 | R11: -9.52 | S11: 4.61 | T11: 3.366
A12: J. Informasi dan Komunikasi | B12: 4.76 | C12: 5.12 | D12: 5.25 | E12: 5.3 | F12: 6.29 | G12: 6.2 | H12: =AVERAGE(B12:G12) -> 5.4866667 | I12: =B12*$B$20/100 -> 122598.46 | J12: =C12*$C$20/100 -> 139184.45 | K12: =D12*$D$20/100 -> 153358.46 | L12: =E12*$E$20/100 -> 161917.16 | M12: =F12*$F$20/100 -> 181850.68 | N12: =G12*$G$20 -> 28960668 | O12: 11.35 | P12: 10.57 | Q12: 7.17 | R12: 17.32 | S12: 2.21 | T12: 9.724
A13: K. Jasa Keuangan dan Asuransi | B13: 5.15 | C13: 5.19 | D13: 5.15 | E13: 5.06 | F13: 5.19 | G13: 5.17 | H13: =AVERAGE(B13:G13) -> 5.1516667 | I13: =B13*$B$20/100 -> 132643.3 | J13: =C13*$C$20/100 -> 141087.37 | K13: =D13*$D$20/100 -> 150437.34 | L13: =E13*$E$20/100 -> 154585.06 | M13: =F13*$F$20/100 -> 150048.5 | N13: =G13*$G$20 -> 24149460 | O13: 4.67 | P13: 3.55 | Q13: 3.79 | R13: 1.2 | S13: 0.8 | T13: 2.802
A14: L. Real Estate | B14: 3.21 | C14: 3.18 | D14: 3.2 | E14: 3.13 | F14: 3.17 | G14: 3.1 | H14: =AVERAGE(B14:G14) -> 3.165 | I14: =B14*$B$20/100 -> 82676.696 | J14: =C14*$C$20/100 -> 86446.594 | K14: =D14*$D$20/100 -> 93475.63 | L14: =E14*$E$20/100 -> 95622.776 | M14: =F14*$F$20/100 -> 91648.118 | N14: =G14*$G$20 -> 14480334 | O14: 4.71 | P14: 5.46 | Q14: 3.42 | R14: -0.46 | S14: 2.14 | T14: 3.054
A15: M,N . Jasa Perusahaan | B15: 0.35 | C15: 0.36 | D15: 0.37 | E15: 0.39 | F15: 0.38 | G15: 0.37 | H15: =AVERAGE(B15:G15) -> 0.37 | I15: =B15*$B$20/100 -> 9014.593 | J15: =C15*$C$20/100 -> 9786.4068 | K15: =D15*$D$20/100 -> 10808.12 | L15: =E15*$E$20/100 -> 11914.659 | M15: =F15*$F$20/100 -> 10986.21 | N15: =G15*$G$20 -> 1728297.9 | O15: 7.84 | P15: 8.16 | Q15: 8.68 | R15: -6.25 | S15: 1.45 | T15: 3.976
A16: O. Administrasi Pemerintahan, Pertahanan dan Jaminan Sosial Wajib | B16: 12.04 | C16: 11.74 | D16: 11.38 | E16: 11.11 | F16: 11.22 | G16: 10.87 | H16: =AVERAGE(B16:G16) -> 11.393333 | I16: =B16*$B$20/100 -> 310102 | J16: =C16*$C$20/100 -> 319145.6 | K16: =D16*$D$20/100 -> 332422.71 | L16: =E16*$E$20/100 -> 339415.03 | M16: =F16*$F$20/100 -> 324382.3 | N16: =G16*$G$20 -> 50774590 | O16: 2.28 | P16: 3.37 | Q16: 3.42 | R16: -1.58 | S16: 1.66 | T16: 1.83
... A19: R,S,T,U. Jasa Lainnya | B19: 2 | C19: 2.06 | D19: 2.1 | E19: 2.15 | F19: 2.04 | G19: 1.97 | H19: =AVERAGE(B19:G19) -> 2.0533333 | I19: =B19*$B$20/100 -> 51511.96 | J19: =C19*$C$20/100 -> 55999.995 | K19: =D19*$D$20/100 -> 61343.382 | L19: =E19*$E$20/100 -> 65683.377 | M19: =F19*$F$20/100 -> 58978.6 | N19: =G19*$G$20 -> 9202018.7 | O19: 9.26 | P19: 9.3 | Q19: 8.84 | R19: -7.03 | S19: 1.04 | T19: 4.282
A20: Pembentukan Modal Tetap Bruto (Juta Rupiah) | B20: 2575598 | C20: 2718446.3 | D20: 2921113.4 | E20: 3055040.8 | F20: 2891107.8 | G20: 4671075.5 | H20: =AVERAGE(B20:G20) -> 3138730.3 | I20: =B20 -> 2575598 | J20: =C20 -> 2718446.3 | K20: =D20 -> 2921113.4 | L20: =E20 -> 3055040.8 | M20: =F20 -> 2891107.8 | N20: =G20 -> 4671075.5
A22: PRODUK DOMESTIK REGIONAL BRUTO | B22: 6513894.7 | C22: 6312054.4 | D22: 6470539.5 | E22: 6138622.8 | F22: 5820532 | G22: 5521525.5 | H22: 5521525.5

Sheet ICOR
A1: Sektor Potensial Kota Magelang | B1: 2016 | D1: 2017 | F1: 2018 | H1: 2019 | J1: 2020 | L1: 2021
B3: Output | C3: Investasi | D3: Output | E3: Investasi | F3: Output | G3: Investasi | H3: Output | I3: Investasi | J3: Output | K3: Investasi | L3: Output | M3: Investasi
A4: A. Pertanian, Kehutanan, dan Perikanan | B4: =LQ!H4 -> 106735.73 | C4: ='RASIO INVESTASI'!I3 -> 49966.601 | D4: =LQ!F4 -> 108869.6 | E4: ='RASIO INVESTASI'!J3 -> 50563.102 | F4: =LQ!E4 -> 109809.02 | G4: ='RASIO INVESTASI'!K3 -> 52580.042 | H4: =LQ!D4 -> 115481.55 | I4: ='RASIO INVESTASI'!L3 -> 55296.238 | J4: =LQ!C4 -> 116340.03 | K4: ='RASIO INVESTASI'!M3 -> 53774.605 | L4: =LQ!B4 -> 116787.02 | M4: ='RASIO INVESTASI'!I3 -> 49966.601
A5: B. Pertambangan dan Penggalian | B5: =LQ!H5 -> 0 | C5: ='RASIO INVESTASI'!I4 -> 0 | D5: =LQ!F5 -> 0 | E5: ='RASIO INVESTASI'!J4 -> 0 | F5: =LQ!E5 -> 0 | G5: ='RASIO INVESTASI'!K4 -> 0 | H5: =LQ!D5 -> 0 | I5: ='RASIO INVESTASI'!L4 -> 0 | J5: =LQ!C5 -> 0 | K5: ='RASIO INVESTASI'!M4 -> 0 | L5: =LQ!B5 -> 0 | M5: ='RASIO INVESTASI'!I4 -> 0
A6: C. Industri Pengolahan | B6: =LQ!H6 -> 828143.74 | C6: ='RASIO INVESTASI'!I5 -> 416731.76 | D6: =LQ!F6 -> 864272.22 | E6: ='RASIO INVESTASI'!J5 -> 436582.48 | F6: =LQ!E6 -> 894350.14 | G6: ='RASIO INVESTASI'!K5 -> 462120.15 | H6: =LQ!D6 -> 934870.61 | I6: ='RASIO INVESTASI'!L5 -> 477197.37 | J6: =LQ!C6 -> 932910.91 | K6: ='RASIO INVESTASI'!M5 -> 466335.69 | L6: =LQ!B6 -> 976664.1 | M6: ='RASIO INVESTASI'!I5 -> 416731.76
A7: D. Pengadaan Listrik dan Gas | B7: =LQ!H7 -> 19086.34 | C7: ='RASIO INVESTASI'!I6 -> 7211.6744 | D7: =LQ!F7 -> 19887.1 | E7: ='RASIO INVESTASI'!J6 -> 7883.4944 | F7: =LQ!E7 -> 21149.94 | G7: ='RASIO INVESTASI'!K6 -> 8763.3403 | H7: =LQ!D7 -> 22379.92 | I7: ='RASIO INVESTASI'!L6 -> 8859.6182 | J7: =LQ!C7 -> 22782.58 | K7: ='RASIO INVESTASI'!M6 -> 8673.3235 | L7: =LQ!B7 -> 24999.35 | M7: ='RASIO INVESTASI'!I6 -> 7211.6744
A8: E. Pengadaan Air, Pengelolaan Sampah, Limbah dan Daur Ulang | B8: =LQ!H8 -> 7868.22 | C8: ='RASIO INVESTASI'!I7 -> 3348.2774 | D8: =LQ!F8 -> 8228.4 | E8: ='RASIO INVESTASI'!J7 -> 3262.1356 | F8: =LQ!E8 -> 8569.3 | G8: ='RASIO INVESTASI'!K7 -> 3505.3361 | H8: =LQ!D8 -> 8914.87 | I8: ='RASIO INVESTASI'!L7 -> 3666.0489 | J8: =LQ!C8 -> 8872.97 | K8: ='RASIO INVESTASI'!M7 -> 3758.4402 | L8: =LQ!B8 -> 8891.03 | M8: ='RASIO INVESTASI'!I7 -> 3348.2774
A9: F. Konstruksi | B9: =LQ!H9 -> 907490.87 | C9: ='RASIO INVESTASI'!I8 -> 426519.03 | D9: =LQ!F9 -> 952201.56 | E9: ='RASIO INVESTASI'!J8 -> 448815.49 | F9: =LQ!E9 -> 1000726.3 | G9: ='RASIO INVESTASI'!K8 -> 490454.95 | H9: =LQ!D9 -> 1041119.1 | I9: ='RASIO INVESTASI'!L8 -> 512024.83 | J9: =LQ!C9 -> 1021386.1 | K9: ='RASIO INVESTASI'!M8 -> 482236.78 | L9: =LQ!B9 -> 1054427.4 | M9: ='RASIO INVESTASI'!I8 -> 426519.03
A10: G. Perdagangan Besar dan Eceran; Reparasi Mobil dan Sepeda Motor | B10: =LQ!H10 -> 844737.97 | C10: ='RASIO INVESTASI'!I9 -> 369598.31 | D10: =LQ!F10 -> 889686.2 | E10: ='RASIO INVESTASI'!J9 -> 388465.98 | F10: =LQ!E10 -> 941850.09 | G10: ='RASIO INVESTASI'!K9 -> 420640.34 | H10: =LQ!D10 -> 994030.89 | I10: ='RASIO INVESTASI'!L9 -> 443286.42 | J10: =LQ!C10 -> 959216.92 | K10: ='RASIO INVESTASI'!M9 -> 413717.53 | L10: =LQ!B10 -> 1010890.7 | M10: ='RASIO INVESTASI'!I9 -> 369598.31
A11: H. Transportasi dan Pergudangan | B11: =LQ!H11 -> 418762 | C11: ='RASIO INVESTASI'!I10 -> 173852.86 | D11: =LQ!F11 -> 443250.98 | E11: ='RASIO INVESTASI'!J10 -> 181864.06 | F11: =LQ!E11 -> 472092.23 | G11: ='RASIO INVESTASI'!K10 -> 194546.16 | H11: =LQ!D11 -> 511366.87 | I11: ='RASIO INVESTASI'!L10 -> 208964.79 | J11: =LQ!C11 -> 371393.25 | K11: ='RASIO INVESTASI'!M10 -> 150337.61 | L11: =LQ!B11 -> 381908.37 | M11: ='RASIO INVESTASI'!I10 -> 173852.86
A12: I. Penyediaan Akomodasi dan Makan Minum | B12: =LQ!H12 -> 318041.12 | C12: ='RASIO INVESTASI'!I11 -> 154020.76 | D12: =LQ!F12 -> 337687.35 | E12: ='RASIO INVESTASI'!J11 -> 160932.02 | F12: =LQ!E12 -> 360973.97 | G12: ='RASIO INVESTASI'!K11 -> 173222.03 | H12: =LQ!D12 -> 392225.82 | I12: ='RASIO INVESTASI'!L11 -> 185440.97 | J12: =LQ!C12 -> 354869.82 | K12: ='RASIO INVESTASI'!M11 -> 161323.82 | L12: =LQ!B12 -> 371237.65 | M12: ='RASIO INVESTASI'!I11 -> 154020.76
A13: J. Informasi dan Komunikasi | B13: =LQ!H13 -> 347340.64 | C13: ='RASIO INVESTASI'!I12 -> 122598.46 | D13: =LQ!F13 -> 386751.83 | E13: ='RASIO INVESTASI'!J12 -> 139184.45 | F13: =LQ!E13 -> 427612.45 | G13: ='RASIO INVESTASI'!K12 -> 153358.46 | H13: =LQ!D13 -> 458256.15 | I13: ='RASIO INVESTASI'!L12 -> 161917.16 | J13: =LQ!C13 -> 537630.7 | K13: ='RASIO INVESTASI'!M12 -> 181850.68 | L13: =LQ!B13 -> 549524.44 | M13: ='RASIO INVESTASI'!I12 -> 122598.46
A14: K. Jasa Keuangan dan Asuransi | B14: =LQ!H14 -> 272244.6 | C14: ='RASIO INVESTASI'!I13 -> 132643.3 | D14: =LQ!F14 -> 284960.96 | E14: ='RASIO INVESTASI'!J13 -> 141087.37 | F14: =LQ!E14 -> 295081.77 | G14: ='RASIO INVESTASI'!K13 -> 150437.34 | H14: =LQ!D14 -> 306268.29 | I14: ='RASIO INVESTASI'!L13 -> 154585.06 | J14: =LQ!C14 -> 309950.91 | K14: ='RASIO INVESTASI'!M13 -> 150048.5 | L14: =LQ!B14 -> 312431.71 | M14: ='RASIO INVESTASI'!I13 -> 132643.3
A15: L. Real Estate | B15: =LQ!H15 -> 196818.98 | C15: ='RASIO INVESTASI'!I14 -> 82676.696 | D15: =LQ!F15 -> 206097.24 | E15: ='RASIO INVESTASI'!J14 -> 86446.594 | F15: =LQ!E15 -> 217344.58 | G15: ='RASIO INVESTASI'!K14 -> 93475.63 | H15: =LQ!D15 -> 224784.9 | I15: ='RASIO INVESTASI'!L14 -> 95622.776 | J15: =LQ!C15 -> 223750.89 | K15: ='RASIO INVESTASI'!M14 -> 91648.118 | L15: =LQ!B15 -> 228544.53 | M15: ='RASIO INVESTASI'!I14 -> 82676.696
... A20: R,S,T,U. Jasa Lainnya | B20: =LQ!H20 -> 114313.07 | C20: ='RASIO INVESTASI'!I19 -> 51511.96 | D20: =LQ!F20 -> 124894.17 | E20: ='RASIO INVESTASI'!J19 -> 55999.995 | F20: =LQ!E20 -> 136505.66 | G20: ='RASIO INVESTASI'!K19 -> 61343.382 | H20: =LQ!D20 -> 148576.93 | I20: ='RASIO INVESTASI'!L19 -> 65683.377 | J20: =LQ!C20 -> 138139.4 | K20: ='RASIO INVESTASI'!M19 -> 58978.6 | L20: =LQ!B20 -> 139579.02 | M20: ='RASIO INVESTASI'!I19 -> 51511.96
A22: Sektor Potensial Kota Magelang | B22: Koefisien ICOR 2017 | C22: Koefisien ICOR 2018 | D22: Koefisien ICOR 2019 | E22: Koefisien ICOR 2020 | F22: Koefisien ICOR 2021 | G22: Rata-rata Nilai ICOR
H23: jenis sektor potensialnya tolong nanti di sesuaikan seperti pada sheet LQ yang udah di highlight kuning. Dipahami dulu sperti pada contoh
A25: A. Pertanian, Kehutanan, dan Perikanan | B25: =E4/(D4-B4) -> 23.695493 | C25: =G4/(F4-D4) -> 55.97075 | D25: =I4/(H4-F4) -> 9.7480732 | E25: =K4/(J4-H4) -> 62.639322 | F25: =M4/(L4-J4) -> 111.78461 | G25: =AVERAGE(B25:F25) -> 52.767649
A26: B. Pertambangan dan Penggalian | B26: =E5/(D5-B5) -> #DIV/0! | C26: =G5/(F5-D5) -> #DIV/0! | D26: =I5/(H5-F5) -> #DIV/0! | E26: =K5/(J5-H5) -> #DIV/0! | F26: =M5/(L5-J5) -> #DIV/0! | G26: =AVERAGE(B26:F26) -> #DIV/0!
A27: C. Industri Pengolahan | B27: =E6/(D6-B6) -> 12.084164 | C27: =G6/(F6-D6) -> 15.364099 | D27: =I6/(H6-F6) -> 11.776699 | E27: =K6/(J6-H6) -> -237.9628 | F27: =M6/(L6-J6) -> 9.5246028 | G27: =AVERAGE(B27:F27) -> -37.842646
A28: D. Pengadaan Listrik dan Gas | B28: =E7/(D7-B7) -> 9.8450152 | C28: =G7/(F7-D7) -> 6.9393908 | D28: =I7/(H7-F7) -> 7.2030588 | E28: =K7/(J7-H7) -> 21.540067 | F28: =M7/(L7-J7) -> 3.2532353 | G28: =AVERAGE(B28:F28) -> 9.7561535
A29: E. Pengadaan Air, Pengelolaan Sampah, Limbah dan Daur Ulang | B29: =E8/(D8-B8) -> 9.0569593 | C29: =G8/(F8-D8) -> 10.282594 | D29: =I8/(H8-F8) -> 10.608701 | E29: =K8/(J8-H8) -> -89.700243 | F29: =M8/(L8-J8) -> 185.39742 | G29: =AVERAGE(B29:F29) -> 25.129086
A30: F. Konstruksi | B30: =E9/(D9-B9) -> 10.038214 | C30: =G9/(F9-D9) -> 10.107324 | D30: =I9/(H9-F9) -> 12.676138 | E30: =K9/(J9-H9) -> -24.438063 | F30: =M9/(L9-J9) -> 12.908636 | G30: =AVERAGE(B30:F30) -> 4.2584499
A31: G. Perdagangan Besar dan Eceran; Reparasi Mobil dan Sepeda Motor | B31: =E10/(D10-B10) -> 8.6425201 | C31: =G10/(F10-D10) -> 8.0638222 | D31: =I10/(H10-F10) -> 8.4952016 | E31: =K10/(J10-H10) -> -11.883664 | F31: =M10/(L10-J10) -> 7.1525365 | G31: =AVERAGE(B31:F31) -> 4.0940833
A32: H. Transportasi dan Pergudangan | B32: =E11/(D11-B11) -> 7.4263632 | C32: =G11/(F11-D11) -> 6.7454134 | D32: =I11/(H11-F11) -> 5.3206035 | E32: =K11/(J11-H11) -> -1.0740424 | F32: =M11/(L11-J11) -> 16.533607 | G32: =AVERAGE(B32:F32) -> 6.990389
A33: I. Penyediaan Akomodasi dan Makan Minum | B33: =E12/(D12-B12) -> 8.1914965 | C33: =G12/(F12-D12) -> 7.4386934 | D33: =I12/(H12-F12) -> 5.9337599 | E33: =K12/(J12-H12) -> -4.3185517 | F33: =M12/(L12-J12) -> 9.4099682 | G33: =AVERAGE(B33:F33) -> 5.3310733
A34: J. Informasi dan Komunikasi | B34: =E13/(D13-B13) -> 3.5315973 | C34: =G13/(F13-D13) -> 3.7532092 | D34: =I13/(H13-F13) -> 5.2838646 | E34: =K13/(J13-H13) -> 2.2910452 | F34: =M13/(L13-J13) -> 10.307814 | G34: =AVERAGE(B34:F34) -> 5.0335061
A35: K. Jasa Keuangan dan Asuransi | B35: =E14/(D14-B14) -> 11.094949 | C35: =G14/(F14-D14) -> 14.86416 | D35: =I14/(H14-F14) -> 13.81887 | E35: =K14/(J14-H14) -> 40.745039 | F35: =M14/(L14-J14) -> 53.467953 | G35: =AVERAGE(B35:F35) -> 26.798194
A36: L. Real Estate | B36: =E15/(D15-B15) -> 9.3171126 | C36: =G15/(F15-D15) -> 8.31091 | D36: =I15/(H15-F15) -> 12.851971 | E36: =K15/(J15-H15) -> -88.633686 | F36: =M15/(L15-J15) -> 17.247164 | G36: =AVERAGE(B36:F36) -> -8.1813057
... A41: R,S,T,U. Jasa Lainnya | B41: =E20/(D20-B20) -> 5.2924549 | C41: =G20/(F20-D20) -> 5.2829897 | D41: =I20/(H20-F20) -> 5.4412979 | E41: =K20/(J20-H20) -> -5.650628 | F41: =M20/(L20-J20) -> 35.781637 | G41: =AVERAGE(B41:F41) -> 9.2295503

Sheet KEBUTUHAN INVESTASI
A1: Sektor Potensial Kota Magelang | B1: PDRB 2021 | C1: Rata-rata Nilai ICOR | D1: PDRB 2020 (6.00%) | E1: Kebutuhan Investasi 2021 (6.00%) | G1: Sektor Potensial Kota Magelang | H1: PDRB 2016 | I1: Rata-rata Nilai ICOR | J1: Pertumbuhan (5.6%) | K1: Kebutuhan Investasi 2017 (6.00%)
A2: D. Pengadaan Listrik dan Gas | B2: =ICOR!L7 -> 24999.35 | C2: =ICOR!G28 -> 9.7561535 | D2: =B2-(B2*6%) -> 23499.389 | E2: =C2*(B2-D2) -> 14633.85 | G2: D. Pengadaan Listrik dan Gas | H2: =ICOR!B7 -> 19086.34 | I2: =C2 -> 9.7561535 | J2: =H2+(H2*5.6%) -> 20155.175 | K2: =I2*(J2-H2) -> 10427.719
A3: E. Pengadaan Air, Pengelolaan Sampah, Limbah dan Daur Ulang | B3: =ICOR!L8 -> 8891.03 | C3: =ICOR!G29 -> 25.129086 | D3: =B3-(B3*6%) -> 8357.5682 | E3: =C3*(B3-D3) -> 13405.408 | G3: E. Pengadaan Air, Pengelolaan Sampah, Limbah dan Daur Ulang | H3: =ICOR!B8 -> 7868.22 | I3: =C3 -> 25.129086 | J3: =H3+(H3*5.6%) -> 8308.8403 | K3: =I3*(J3-H3) -> 11072.386
A4: F. Konstruksi | B4: =ICOR!L9 -> 1054427.4 | C4: =ICOR!G30 -> 4.2584499 | D4: =B4-(B4*6%) -> 991161.78 | E4: =C4*(B4-D4) -> 269413.58 | G4: F. Konstruksi | H4: =ICOR!B9 -> 907490.87 | I4: =C4 -> 4.2584499 | J4: =H4+(H4*5.6%) -> 958310.36 | K4: =I4*(J4-H4) -> 216412.25
A5: G. Perdagangan Besar dan Eceran; Reparasi Mobil dan Sepeda Motor | B5: =ICOR!L10 -> 1010890.7 | C5: =ICOR!G31 -> 4.0940833 | D5: =B5-(B5*6%) -> 950237.22 | E5: =C5*(B5-D5) -> 248320.23 | G5: G. Perdagangan Besar dan Eceran; Reparasi Mobil dan Sepeda Motor | H5: =ICOR!B10 -> 844737.97 | I5: =C5 -> 4.0940833 | J5: =H5+(H5*5.6%) -> 892043.3 | K5: =I5*(J5-H5) -> 193671.94
A6: H. Transportasi dan Pergudangan | B6: =ICOR!L11 -> 381908.37 | C6: =ICOR!G32 -> 6.990389 | D6: =B6-(B6*6%) -> 358993.87 | E6: =C6*(B6-D6) -> 160181.28 | G6: H. Transportasi dan Pergudangan | H6: =ICOR!B11 -> 418762 | I6: =C6 -> 6.990389 | J6: =H6+(H6*5.6%) -> 442212.67 | K6: =I6*(J6-H6) -> 163929.32
A7: I. Penyediaan Akomodasi dan Makan Minum | B7: =ICOR!L12 -> 371237.65 | C7: =ICOR!G33 -> 5.3310733 | D7: =B7-(B7*6%) -> 348963.39 | E7: =C7*(B7-D7) -> 118745.71 | G7: I. Penyediaan Akomodasi dan Makan Minum | H7: =ICOR!B12 -> 318041.12 | I7: =C7 -> 5.3310733 | J7: =H7+(H7*5.6%) -> 335851.42 | K7: =I7*(J7-H7) -> 94948.029
A8: J. Informasi dan Komunikasi | B8: =ICOR!L13 -> 549524.44 | C8: =ICOR!G34 -> 5.0335061 | D8: =B8-(B8*6%) -> 516552.97 | E8: =C8*(B8-D8) -> 165962.08 | G8: J. Informasi dan Komunikasi | H8: =ICOR!B13 -> 347340.64 | I8: =C8 -> 5.0335061 | J8: =H8+(H8*5.6%) -> 366791.72 | K8: =I8*(J8-H8) -> 97907.11
A9: K. Jasa Keuangan dan Asuransi | B9: =ICOR!L14 -> 312431.71 | C9: =ICOR!G35 -> 26.798194 | D9: =B9-(B9*6%) -> 293685.81 | E9: =C9*(B9-D9) -> 502356.34 | G9: K. Jasa Keuangan dan Asuransi | H9: =ICOR!B14 -> 272244.6 | I9: =C9 -> 26.798194 | J9: =H9+(H9*5.6%) -> 287490.3 | K9: =I9*(J9-H9) -> 408557.16
A10: L. Real Estate | B10: =ICOR!L15 -> 228544.53 | C10: =ICOR!G36 -> -8.1813057 | D10: =B10-(B10*6%) -> 214831.86 | E10: =C10*(B10-D10) -> -112187.56 | G10: L. Real Estate | H10: =ICOR!B15 -> 196818.98 | I10: =C10 -> -8.1813057 | J10: =H10+(H10*5.6%) -> 207840.84 | K10: =I10*(J10-H10) -> -90173.23
A11: O. Administrasi Pemerintahan, Pertahanan dan Jaminan Sosial Wajib | B11: =ICOR!L17 -> 672846.92 | C11: =ICOR!G38 -> 10.276605 | D11: =B11-(B11*6%) -> 632476.1 | E11: =C11*(B11-D11) -> 414874.92 | G11: O. Administrasi Pemerintahan, Pertahanan dan Jaminan Sosial Wajib | H11: =ICOR!B16 -> 19446.7 | I11: =C11 -> 10.276605 | J11: =H11+(H11*5.6%) -> 20535.715 | K11: =I11*(J11-H11) -> 11191.379
A12: P. Jasa Pendidikan | B12: =ICOR!L18 -> 443980.97 | C12: =ICOR!G39 -> -45.33204 | D12: =B12-(B12*6%) -> 417342.11 | E12: =C12*(B12-D12) -> -1207593.8 | G12: P. Jasa Pendidikan | H12: =ICOR!B17 -> 615023.35 | I12: =C12 -> -45.33204 | J12: =H12+(H12*5.6%) -> 649464.66 | K12: =I12*(J12-H12) -> -1561294.7
A13: Q. Jasa Kesehatan dan Kegiatan Sosial | B13: =ICOR!L19 -> 197738.53 | C13: =ICOR!G40 -> 14.203139 | D13: =B13-(B13*6%) -> 185874.22 | E13: =C13*(B13-D13) -> 168510.47 | G13: Q. Jasa Kesehatan dan Kegiatan Sosial | H13: =ICOR!B18 -> 360681.63 | I13: =C13 -> 14.203139 | J13: =H13+(H13*5.6%) -> 380879.8 | K13: =I13*(J13-H13) -> 286877.44
A14: R,S,T,U. Jasa Lainnya | B14: =ICOR!L20 -> 139579.02 | C14: =ICOR!G41 -> 9.2295503 | D14: =B14-(B14*6%) -> 131204.28 | E14: =C14*(B14-D14) -> 77295.095 | G14: R,S,T,U. Jasa Lainnya | H14: =ICOR!B19 -> 144790.58 | I14: =C14 -> 9.2295503 | J14: =H14+(H14*5.6%) -> 152898.85 | K14: =I14*(J14-H14) -> 74835.708
A17: Sektor Potensial Kota Magelang | B17: PDRB 2020 | C17: Rata-rata Nilai ICOR | D17: PDRB 2019 (6.00%) | E17: Kebutuhan Investasi 2020 (6.00%) | G17: Sektor Potensial Kota Magelang | H17: PDRB 2017 | I17: Rata-rata Nilai ICOR | J17: Pertumbuhan (5.6%) | K17: Kebutuhan Investasi 2018 (6.00%)
A18: D. Pengadaan Listrik dan Gas | B18: =ICOR!J7 -> 22782.58 | C18: =C2 -> 9.7561535 | D18: =B18-(B18*6%) -> 21415.625 | E18: =C18*(B18-D18) -> 13336.221 | G18: D. Pengadaan Listrik dan Gas | H18: =ICOR!D7 -> 19887.1 | I18: =C2 -> 9.7561535 | J18: =H18+(H18*5.6%) -> 21000.778 | K18: =I18*(J18-H18) -> 10865.21
A19: E. Pengadaan Air, Pengelolaan Sampah, Limbah dan Daur Ulang | B19: =ICOR!J8 -> 8872.97 | C19: =C3 -> 25.129086 | D19: =B19-(B19*6%) -> 8340.5918 | E19: =C19*(B19-D19) -> 13378.178 | G19: E. Pengadaan Air, Pengelolaan Sampah, Limbah dan Daur Ulang | H19: =ICOR!D8 -> 8228.4 | I19: =C3 -> 25.129086 | J19: =H19+(H19*5.6%) -> 8689.1904 | K19: =I19*(J19-H19) -> 11579.242
A20: F. Konstruksi | B20: =ICOR!J9 -> 1021386.1 | C20: =C4 -> 4.2584499 | D20: =B20-(B20*6%) -> 960102.9 | E20: =C20*(B20-D20) -> 260971.28 | G20: F. Konstruksi | H20: =ICOR!D9 -> 952201.56 | I20: =C4 -> 4.2584499 | J20: =H20+(H20*5.6%) -> 1005524.8 | K20: =I20*(J20-H20) -> 227074.55
A21: G. Perdagangan Besar dan Eceran; Reparasi Mobil dan Sepeda Motor | B21: =ICOR!J10 -> 959216.92 | C21: =C5 -> 4.0940833 | D21: =B21-(B21*6%) -> 901663.9 | E21: =C21*(B21-D21) -> 235626.84 | G21: G. Perdagangan Besar dan Eceran; Reparasi Mobil dan Sepeda Motor | H21: =ICOR!D10 -> 889686.2 | I21: =C5 -> 4.0940833 | J21: =H21+(H21*5.6%) -> 939508.63 | K21: =I21*(J21-H21) -> 203977.16
A22: H. Transportasi dan Pergudangan | B22: =ICOR!J11 -> 371393.25 | C22: =C6 -> 6.990389 | D22: =B22-(B22*6%) -> 349109.66 | E22: =C22*(B22-D22) -> 155771 | G22: H. Transportasi dan Pergudangan | H22: =ICOR!D11 -> 443250.98 | I22: =C6 -> 6.990389 | J22: =H22+(H22*5.6%) -> 468073.03 | K22: =I22*(J22-H22) -> 173515.82
A23: I. Penyediaan Akomodasi dan Makan Minum | B23: =ICOR!J12 -> 354869.82 | C23: =C7 -> 5.3310733 | D23: =B23-(B23*6%) -> 333577.63 | E23: =C23*(B23-D23) -> 113510.22 | G23: I. Penyediaan Akomodasi dan Makan Minum | H23: =ICOR!D12 -> 337687.35 | I23: =C7 -> 5.3310733 | J23: =H23+(H23*5.6%) -> 356597.84 | K23: =I23*(J23-H23) -> 100813.22
A24: J. Informasi dan Komunikasi | B24: =ICOR!J13 -> 537630.7 | C24: =C8 -> 5.0335061 | D24: =B24-(B24*6%) -> 505372.86 | E24: =C24*(B24-D24) -> 162370.05 | G24: J. Informasi dan Komunikasi | H24: =ICOR!D13 -> 386751.83 | I24: =C8 -> 5.0335061 | J24: =H24+(H24*5.6%) -> 408409.93 | K24: =I24*(J24-H24) -> 109016.19
A25: K. Jasa Keuangan dan Asuransi | B25: =ICOR!J14 -> 309950.91 | C25: =C9 -> 26.798194 | D25: =B25-(B25*6%) -> 291353.86 | E25: =C25*(B25-D25) -> 498367.48 | G25: K. Jasa Keuangan dan Asuransi | H25: =ICOR!D14 -> 284960.96 | I25: =C9 -> 26.798194 | J25: =H25+(H25*5.6%) -> 300918.77 | K25: =I25*(J25-H25) -> 427640.59
A26: L. Real Estate | B26: =ICOR!J15 -> 223750.89 | C26: =C10 -> -8.1813057 | D26: =B26-(B26*6%) -> 210325.84 | E26: =C26*(B26-D26) -> -109834.47 | G26: L. Real Estate | H26: =ICOR!D15 -> 206097.24 | I26: =C10 -> -8.1813057 | J26: =H26+(H26*5.6%) -> 217638.69 | K26: =I26*(J26-H26) -> -94424.094
A27: O. Administrasi Pemerintahan, Pertahanan dan Jaminan Sosial Wajib | B27: =ICOR!J17 -> 661857.19 | C27: =C11 -> 10.276605 | D27: =B27-(B27*6%) -> 622145.76 | E27: =C27*(B27-D27) -> 408098.7 | G27: O. Administrasi Pemerintahan, Pertahanan dan Jaminan Sosial Wajib | H27: =ICOR!D17 -> 629054.75 | I27: =C11 -> 10.276605 | J27: =H27+(H27*5.6%) -> 664281.82 | K27: =I27*(J27-H27) -> 362014.64
A28: P. Jasa Pendidikan | B28: =ICOR!J18 -> 433747.02 | C28: =C12 -> -45.33204 | D28: =B28-(B28*6%) -> 407722.2 | E28: =C28*(B28-D28) -> -1179758.2 | G28: P. Jasa Pendidikan | H28: =ICOR!D18 -> 386306.42 | I28: =C12 -> -45.33204 | J28: =H28+(H28*5.6%) -> 407939.58 | K28: =I28*(J28-H28) -> -980675.26
A29: Q. Jasa Kesehatan dan Kegiatan Sosial | B29: =ICOR!J19 -> 196096.83 | C29: =C13 -> 14.203139 | D29: =B29-(B29*6%) -> 184331.02 | E29: =C29*(B29-D29) -> 167111.44 | G29: Q. Jasa Kesehatan dan Kegiatan Sosial | H29: =ICOR!D19 -> 157412.71 | I29: =C13 -> 14.203139 | J29: =H29+(H29*5.6%) -> 166227.82 | K29: =I29*(J29-H29) -> 125202.26
A30: R,S,T,U. Jasa Lainnya | B30: =ICOR!J20 -> 138139.4 | C30: =C14 -> 9.2295503 | D30: =B30-(B30*6%) -> 129851.04 | E30: =C30*(B30-D30) -> 76497.872 | G30: R,S,T,U. Jasa Lainnya | H30: =ICOR!D20 -> 124894.17 | I30: =C14 -> 9.2295503 | J30: =H30+(H30*5.6%) -> 131888.24 | K30: =I30*(J30-H30) -> 64552.153
A33: Sektor Potensial Kota Magelang | B33: PDRB 2019 | C33: Rata-rata Nilai ICOR | D33: PDRB 2018 (6.00%) | E33: Kebutuhan Investasi 2019 (6.00%) | G33: Sektor Potensial Kota Magelang | H33: PDRB 2018 | I33: Rata-rata Nilai ICOR | J33: Pertumbuhan (5.6%) | K33: Kebutuhan Investasi 2019 (6.00%)
A34: D. Pengadaan Listrik dan Gas | B34: =ICOR!H7 -> 22379.92 | C34: =C2 -> 9.7561535 | D34: =B34-(B34*6%) -> 21037.125 | E34: =C34*(B34-D34) -> 13100.516 | G34: D. Pengadaan Listrik dan Gas | H34: =ICOR!F7 -> 21149.94 | I34: =C2 -> 9.7561535 | J34: =H34+(H34*5.6%) -> 22334.337 | K34: =I34*(J34-H34) -> 11555.155
A35: E. Pengadaan Air, Pengelolaan Sampah, Limbah dan Daur Ulang | B35: =ICOR!H8 -> 8914.87 | C35: =C3 -> 25.129086 | D35: =B35-(B35*6%) -> 8379.9778 | E35: =C35*(B35-D35) -> 13441.352 | G35: E. Pengadaan Air, Pengelolaan Sampah, Limbah dan Daur Ulang | H35: =ICOR!F8 -> 8569.3 | I35: =C19 -> 25.129086 | J35: =H35+(H35*5.6%) -> 9049.1808 | K35: =I35*(J35-H35) -> 12058.966
A36: F. Konstruksi | B36: =ICOR!H9 -> 1041119.1 | C36: =C4 -> 4.2584499 | D36: =B36-(B36*6%) -> 978651.94 | E36: =C36*(B36-D36) -> 266013.2 | G36: F. Konstruksi | H36: =ICOR!F9 -> 1000726.3 | I36: =C20 -> 4.2584499 | J36: =H36+(H36*5.6%) -> 1056766.9 | K36: =I36*(J36-H36) -> 238646.39
A37: G. Perdagangan Besar dan Eceran; Reparasi Mobil dan Sepeda Motor | B37: =ICOR!H10 -> 994030.89 | C37: =C5 -> 4.0940833 | D37: =B37-(B37*6%) -> 934389.04 | E37: =C37*(B37-D37) -> 244178.71 | G37: G. Perdagangan Besar dan Eceran; Reparasi Mobil dan Sepeda Motor | H37: =ICOR!F10 -> 941850.09 | I37: =C21 -> 4.0940833 | J37: =H37+(H37*5.6%) -> 994593.7 | K37: =I37*(J37-H37) -> 215936.71
A38: H. Transportasi dan Pergudangan | B38: =ICOR!H11 -> 511366.87 | C38: =C6 -> 6.990389 | D38: =B38-(B38*6%) -> 480684.86 | E38: =C38*(B38-D38) -> 214479.2 | G38: H. Transportasi dan Pergudangan | H38: =ICOR!F11 -> 472092.23 | I38: =C22 -> 6.990389 | J38: =H38+(H38*5.6%) -> 498529.39 | K38: =I38*(J38-H38) -> 184806.07
A39: I. Penyediaan Akomodasi dan Makan Minum | B39: =ICOR!H12 -> 392225.82 | C39: =C7 -> 5.3310733 | D39: =B39-(B39*6%) -> 368692.27 | E39: =C39*(B39-D39) -> 125459.08 | G39: I. Penyediaan Akomodasi dan Makan Minum | H39: =ICOR!F12 -> 360973.97 | I39: =C23 -> 5.3310733 | J39: =H39+(H39*5.6%) -> 381188.51 | K39: =I39*(J39-H39) -> 107765.21
A40: J. Informasi dan Komunikasi | B40: =ICOR!H13 -> 458256.15 | C40: =C8 -> 5.0335061 | D40: =B40-(B40*6%) -> 430760.78 | E40: =C40*(B40-D40) -> 138398.11 | G40: J. Informasi dan Komunikasi | H40: =ICOR!F13 -> 427612.45 | I40: =C24 -> 5.0335061 | J40: =H40+(H40*5.6%) -> 451558.75 | K40: =I40*(J40-H40) -> 120533.83
A41: K. Jasa Keuangan dan Asuransi | B41: =ICOR!H14 -> 306268.29 | C41: =C9 -> 26.798194 | D41: =B41-(B41*6%) -> 287892.19 | E41: =C41*(B41-D41) -> 492446.23 | G41: K. Jasa Keuangan dan Asuransi | H41: =ICOR!F14 -> 295081.77 | I41: =C25 -> 26.798194 | J41: =H41+(H41*5.6%) -> 311606.35 | K41: =I41*(J41-H41) -> 442828.88
A42: L. Real Estate | B42: =ICOR!H15 -> 224784.9 | C42: =C10 -> -8.1813057 | D42: =B42-(B42*6%) -> 211297.81 | E42: =C42*(B42-D42) -> -110342.04 | G42: L. Real Estate | H42: =ICOR!F15 -> 217344.58 | I42: =C26 -> -8.1813057 | J42: =H42+(H42*5.6%) -> 229515.88 | K42: =I42*(J42-H42) -> -99577.098
A43: O. Administrasi Pemerintahan, Pertahanan dan Jaminan Sosial Wajib | B43: =ICOR!H17 -> 672482.41 | C43: =C11 -> 10.276605 | D43: =B43-(B43*6%) -> 632133.47 | E43: =C43*(B43-D43) -> 414650.17 | G43: O. Administrasi Pemerintahan, Pertahanan dan Jaminan Sosial Wajib | H43: =ICOR!F17 -> 650260.5 | I43: =C27 -> 10.276605 | J43: =H43+(H43*5.6%) -> 686675.09 | K43: =I43*(J43-H43) -> 374218.34
A44: P. Jasa Pendidikan | B44: =ICOR!H18 -> 434616.25 | C44: =C12 -> -45.33204 | D44: =B44-(B44*6%) -> 408539.28 | E44: =C44*(B44-D44) -> -1182122.5 | G44: P. Jasa Pendidikan | H44: =ICOR!F18 -> 409900.3 | I44: =C28 -> -45.33204 | J44: =H44+(H44*5.6%) -> 432854.72 | K44: =I44*(J44-H44) -> -1040570.5
...
