Workbook

Sheet PDRB
A1: Tahun | B1: Nilai PDRB | C1: Laju Pertumbuhan
A2: 2013 | B2: 19848.84
A3: 2014 | B3: 21099.94 | C3: 6.3
A4: 2015 | B4: 22316.88 | C4: 5.77
A5: 2016 | B5: 23623.79 | C5: 5.86
A6: 2017 | B6: 24927.95 | C6: 5.52
A7: 2018

Sheet Peringkat PDRB Jawa Timur
A1: No. | B1: No | C1: Kabupaten | D1: Nilai Total PDRB 2017 | E1: PDRB Jawa Timur | F1: 2014 | G1: 2015 | H1: 2016 | I1: 2017
A2: 15 | B2: 1 | C2: Sidoarjo | D2: 125039.06 | F2: 1262684.5 | G2: 1331376.1 | H2: 1405561 | I2: 1482147.6
A3: 14 | B3: 2 | C3: Pasuruan | D3: 94101.98
A4: 25 | B4: 3 | C4: Gresik | D4: 90855.6
A5: 22 | B5: 4 | C5: Bojonegoro | D5: 63056.47
A6: 7 | B6: 5 | C6: Malang | D6: 61408.93
A7: 16 | B7: 6 | C7: Mojokerto | D7: 52192.83
A8: 10 | B8: 7 | C8: Banyuwangi | D8: 49480.44
A9: 9 | B9: 8 | C9: Jember | D9: 48912.96
A10: 23 | B10: 9 | C10: Tuban | D10: 41037.71
A11: 6 | B11: 10 | C11: Kediri | D11: 26446.17
A12: 17 | B12: 11 | C12: Jombang | D12: 25497
A13: 24 | B13: 12 | C13: Lamongan | D13: 24927.95
A14: 4 | B14: 13 | C14: Tulungagung | D14: 24637.36
... A30: 1 | B30: 29 | C30: Pacitan | D30: 9962.5

Sheet Investasi
A1: Tahun | B1: Investasi Lamongan | C1: Investasi Jawa Timur | D1: Pertumbuhan Investasi Lamongan
A2: 2013 | B2: 6344.15 | D2: 0.0739
A3: 2014 | B3: 6512.54 | C3: 344715.56 | D3: =(B3-B2)/B2 -> 0.026542563
A4: 2015 | B4: 6924.84 | C4: 364831.01 | D4: =(B4-B3)/B3 -> 0.063308632
A5: 2016 | B5: 7455.61 | C5: 386846 | D5: =(B5-B4)/B4 -> 0.076647258
A6: 2017 | B6: 7962.08 | C6: 410312.66 | D6: =(B6-B5)/B5 -> 0.067931397
A10: Tahun | B10: Investasi Bangunan | C10: Investasi Non Bangunan
A11: 2013 | B11: 8.05 | C11: 2.9
A12: 2014 | B12: 2.54 | C12: 3.44
A13: 2015 | B13: 6.72 | C13: 3.57
A14: 2016 | B14: 8.04 | C14: 4.88
A15: 2017 | B15: 6.92 | C15: 5.82
A22: Tahun | B22: PMA | C22: PMDN
A23: 2013 | B23: 60000 | C23: 146385
A24: 2014 | B24: 2502500 | C24: 261650
A25: 2015 | B25: 1938886 | C25: 374133
A26: 2016 | B26: 5552097 | C26: 158156
A27: Total | B27: =SUM(B23:B26) -> 10053483 | C27: =SUM(C23:C26) -> 940324

Sheet Realisasi PMDN
A1: No. | B1: Kabupaten | C1: Realisasi PMDN Jawa Timur
A2: 1 | B2: Sidoarjo | C2: 16.13
A3: 2 | B3: Bondowoso | C3: 3.14
A4: 3 | B4: Sumenep | C4: 2.09
A5: 4 | B5: Jember | C5: 2.02
A6: 5 | B6: Banyuwangi | C6: 1.44
A7: 6 | B7: Mojokerto | C7: 1.34
A8: 7 | B8: Pasuruan | C8: 1.22
A9: 8 | B9: Malang | C9: 1.16
A10: 9 | B10: Tulungagung | C10: 0.73
A11: 10 | B11: Pacitan | C11: 0.7
A12: 11 | B12: Lamongan | C12: 0.62

Sheet SLQ
A1: Sektor Ekonomi | B1: 2013 | D1: Nilai LQ 2013 | E1: 2014 | G1: Nilai LQ 2014 | H1: 2015 | J1: Nilai LQ 2015 | K1: 2016 | M1: Nilai LQ 2016 | N1: Rata-Rata Nilai LQ | O1: Pertumbuhan 2016
B2: Lamongan | C2: Jawa Timur | E2: Lamongan | F2: Jawa Timur | H2: Lamongan | I2: Jawa Timur | K2: Lamongan | L2: Jawa Timur
A3: Pertanian, Kehutanan, dan Perikanan | B3: 7478.6526 | C3: 150463.72 | D3: =(B3/$B$20)/(C3/$C$20) -> 2.986898 | E3: 7851.0617 | F3: 155783.96 | G3: =(E3/$E$20)/(F3/$F$20) -> 3.0159167 | H3: 8212.4295 | I3: 160907.33 | J3: =(H3/$H$20)/(I3/$I$20) -> 3.0448738 | K3: 8567.515 | L3: 164687.46 | M3: =(K3/$K$20)/(L3/$L$20) -> 3.0945252 | N3: =(D3+G3+J3+M3)/4 -> 3.0355534 | O3: =(K3-H3)/H3 -> 0.043237568
A4: Pertambangan dan Penggalian | B4: 244.44558 | C4: 59049.99 | D4: =(B4/$B$20)/(C4/$C$20) -> 0.24876609 | E4: 259.31632 | F4: 60862.35 | G4: =(E4/$E$20)/(F4/$F$20) -> 0.25497337 | H4: 284.31892 | I4: 65707.01 | J4: =(H4/$H$20)/(I4/$I$20) -> 0.25814727 | K4: 294.03572 | L4: 75024.89 | M4: =(K4/$K$20)/(L4/$L$20) -> 0.23312798 | N4: =(D4+G4+J4+M4)/4 -> 0.24875368 | O4: =(K4-H4)/H4 -> 0.034175707
A5: Industri Pengolahan | B5: 1408.4729 | C5: 345794.56 | D5: =(B5/$B$20)/(C5/$C$20) -> 0.24477055 | E5: 1571.8029 | F5: 372316.29 | G5: =(E5/$E$20)/(F5/$F$20) -> 0.25263861 | H5: 1693.0032 | I5: 393272.95 | J5: =(H5/$H$20)/(I5/$I$20) -> 0.25682493 | K5: 1839.3775 | L5: 411028.39 | M5: =(K5/$K$20)/(L5/$L$20) -> 0.26619429 | N5: =(D5+G5+J5+M5)/4 -> 0.25510709 | O5: =(K5-H5)/H5 -> 0.086458379
A6: Pengadaan Listrik dan Gas | B6: 14.98776 | C6: 4380.34 | D6: =(B6/$B$20)/(C6/$C$20) -> 0.20561639 | E6: 15.93118 | F6: 4545.12 | G6: =(E6/$E$20)/(F6/$F$20) -> 0.20975691 | H6: 16.18102 | I6: 4455.27 | J6: =(H6/$H$20)/(I6/$I$20) -> 0.21667327 | K6: 17.62868 | L6: 4483.93 | M6: =(K6/$K$20)/(L6/$L$20) -> 0.23386254 | N6: =(D6+G6+J6+M6)/4 -> 0.21647728 | O6: =(K6-H6)/H6 -> 0.089466548
A7: Pengadaan Air, Pengelolaan Sampah, Limbah dan Daur Ulang | B7: 22.27487 | C7: 1231.05 | D7: =(B7/$B$20)/(C7/$C$20) -> 1.0873474 | E7: 23.04542 | F7: 1234.13 | G7: =(E7/$E$20)/(F7/$F$20) -> 1.1174739 | H7: 24.29698 | I7: 1299.27 | J7: =(H7/$H$20)/(I7/$I$20) -> 1.1156459 | K7: 25.63144 | L7: 1366.77 | M7: =(K7/$K$20)/(L7/$L$20) -> 1.1155197 | N7: =(D7+G7+J7+M7)/4 -> 1.1089967 | O7: =(K7-H7)/H7 -> 0.054922875
A8: Konstruksi | B8: 2162.7305 | C8: 110485.45 | D8: =(B8/$B$20)/(C8/$C$20) -> 1.1763218 | E8: 2271.8577 | F8: 116498.23 | G8: =(E8/$E$20)/(F8/$F$20) -> 1.1670125 | H8: 2309.4811 | I8: 120688.27 | J8: =(H8/$H$20)/(I8/$I$20) -> 1.1416233 | K8: 2455.9043 | L8: 126802.99 | M8: =(K8/$K$20)/(L8/$L$20) -> 1.1520773 | N8: =(D8+G8+J8+M8)/4 -> 1.1592587 | O8: =(K8-H8)/H8 -> 0.063400918
A9: Perdagangan Besar dan Eceran; Reparasi Mobil dan Sepeda Motor | B9: 3807.2506 | C9: 219246.07 | D9: =(B9/$B$20)/(C9/$C$20) -> 1.0435385 | E9: 4105.5492 | F9: 230225.81 | G9: =(E9/$E$20)/(F9/$F$20) -> 1.0671634 | H9: 4401.9166 | I9: 243014.66 | J9: =(H9/$H$20)/(I9/$I$20) -> 1.0806444 | K9: 4709.8119 | L9: 257126.66 | M9: =(K9/$K$20)/(L9/$L$20) -> 1.0895725 | N9: =(D9+G9+J9+M9)/4 -> 1.0702297 | O9: =(K9-H9)/H9 -> 0.069945725
A10: Transportasi dan Pergudangan | B10: 146.398 | C10: 34241.21 | D10: =(B10/$B$20)/(C10/$C$20) -> 0.25693003 | E10: 159.38006 | F10: 36461.76 | G10: =(E10/$E$20)/(F10/$F$20) -> 0.26158332 | H10: 171.505 | I10: 38896.63 | J10: =(H10/$H$20)/(I10/$I$20) -> 0.26304999 | K10: 186.35746 | L10: 41107.64 | M10: =(K10/$K$20)/(L10/$L$20) -> 0.26966459 | N10: =(D10+G10+J10+M10)/4 -> 0.26280698 | O10: =(K10-H10)/H10 -> 0.086600741
A11: Penyediaan Akomodasi dan Makan Minum | B11: 254.6165 | C11: 57684.94 | D11: =(B11/$B$20)/(C11/$C$20) -> 0.26524849 | E11: 279.20693 | F11: 62807.8 | G11: =(E11/$E$20)/(F11/$F$20) -> 0.26602736 | H11: 314.94684 | I11: 67657.04 | J11: =(H11/$H$20)/(I11/$I$20) -> 0.27771398 | K11: 345.93034 | L11: 73398.14 | M11: =(K11/$K$20)/(L11/$L$20) -> 0.28035176 | N11: =(D11+G11+J11+M11)/4 -> 0.2723354 | O11: =(K11-H11)/H11 -> 0.09837692
A12: Informasi dan Komunikasi | B12: 1510.793 | C12: 65313.95 | D12: =(B12/$B$20)/(C12/$C$20) -> 1.3900417 | E12: 1613.5662 | F12: 69155.1 | G12: =(E12/$E$20)/(F12/$F$20) -> 1.3962921 | H12: 1726.9055 | I12: 73639.96 | J12: =(H12/$H$20)/(I12/$I$20) -> 1.3990348 | K12: 1848.5429 | L12: 79216.96 | M12: =(K12/$K$20)/(L12/$L$20) -> 1.3880689 | N12: =(D12+G12+J12+M12)/4 -> 1.3933594 | O12: =(K12-H12)/H12 -> 0.07043661
A13: Jasa Keuangan dan Asuransi | B13: 400.43605 | C13: 30348.35 | D13: =(B13/$B$20)/(C13/$C$20) -> 0.79291551 | E13: 426.03079 | F13: 32399.64 | G13: =(E13/$E$20)/(F13/$F$20) -> 0.78689084 | H13: 456.4697 | I13: 34730.26 | J13: =(H13/$H$20)/(I13/$I$20) -> 0.78411073 | K13: 487.59412 | L13: 37158.62 | M13: =(K13/$K$20)/(L13/$L$20) -> 0.78054612 | N13: =(D13+G13+J13+M13)/4 -> 0.7861158 | O13: =(K13-H13)/H13 -> 0.068185073
A14: Real Estate | B14: 411.26772 | C14: 20565.06 | D14: =(B14/$B$20)/(C14/$C$20) -> 1.2017758 | E14: 444.47561 | F14: 21998.29 | G14: =(E14/$E$20)/(F14/$F$20) -> 1.2091292 | H14: 480.17161 | I14: 23092.64 | J14: =(H14/$H$20)/(I14/$I$20) -> 1.2404989 | K14: 508.72053 | L14: 24298.54 | M14: =(K14/$K$20)/(L14/$L$20) -> 1.2453711 | N14: =(D14+G14+J14+M14)/4 -> 1.2241937 | O14: =(K14-H14)/H14 -> 0.05945566
... A20: PDRB | B20: 19848.838 | C20: 1192789.8 | D20: =(B20/$B$20)/(C20/$C$20) -> 1 | E20: 21099.937 | F20: 1262684.5 | G20: =(E20/$E$20)/(F20/$F$20) -> 1 | H20: 22316.878 | I20: 1331395 | J20: =(H20/$H$20)/(I20/$I$20) -> 1 | K20: 23623.792 | L20: 1405236.1 | M20: =(K20/$K$20)/(L20/$L$20) -> 1 | N20: =(D20+G20+J20+M20)/4 -> 1 | O20: =(K20-H20)/H20 -> 0.058561702

Sheet Rasio Investasi
A1: Sektor Ekonomi | B1: Distribusi Sektor Terhadap PDRB | G1: Nilai Investasi (rasio) | L1: Pertumuhan Per-sektor
B2: 2012 | C2: 2013 | D2: 2014 | E2: 2015 | F2: 2016 | G2: rata-rata | H2: 2013 | I2: 2014 | J2: 2015 | K2: 2016 | L2: 2013 | M2: 2014 | N2: 2015 | O2: 2016 | P2: Rata-rata
A3: Pertanian, Kehutanan, dan Perikanan | C3: 0.37678037 | D3: 0.37208934 | E3: 0.36799186 | F3: 0.36266467 | G3: =AVERAGE(C3:F3) -> 0.36988156 | H3: =C3*$C$20 -> 2390.3512 | I3: =D3*$D$20 -> 2423.2467 | J3: =E3*$E$20 -> 2548.2848 | K3: =F3*$F$20 -> 2703.8864 | L3: 0.058 | M3: 0.0576 | N3: 0.0457 | O3: 0.043237568 | P3: =AVERAGE(L3:O3) -> 0.051134392
A4: Pertambangan dan Penggalian | C4: 0.01231536 | D4: 0.01228991 | E4: 0.012740085 | F4: 0.012446593 | G4: =AVERAGE(C4:F4) -> 0.012447987 | H4: =C4*$C$20 -> 78.130489 | I4: =D4*$D$20 -> 80.038528 | J4: =E4*$E$20 -> 88.223049 | K4: =F4*$F$20 -> 92.79694 | L4: 0.0165 | M4: 0.0608 | N4: 0.0964 | O4: 0.034175707 | P4: =AVERAGE(L4:O4) -> 0.051968927
A5: Industri Pengolahan | C5: 0.070959966 | D5: 0.074493249 | E5: 0.075862008 | F5: 0.077861228 | G5: =AVERAGE(C5:F5) -> 0.074794112 | H5: =C5*$C$20 -> 450.18067 | I5: =D5*$D$20 -> 485.14026 | J5: =E5*$E$20 -> 525.33226 | K5: =F5*$F$20 -> 580.50295 | L5: 0.0694 | M5: 0.0847 | N5: 0.0814 | O5: 0.086458379 | P5: =AVERAGE(L5:O5) -> 0.080489595
A6: Pengadaan Listrik dan Gas | C6: 0.00075509508 | D6: 0.00075503448 | E6: 0.00072505751 | F6: 0.00074622566 | G6: =AVERAGE(C6:F6) -> 0.00074535318 | H6: =C6*$C$20 -> 4.7904365 | I6: =D6*$D$20 -> 4.9171922 | J6: =E6*$E$20 -> 5.0209072 | K6: =F6*$F$20 -> 5.5635675 | L6: 0.0378 | M6: 0.0283 | N6: 0.0045 | O6: 0.089466548 | P6: =AVERAGE(L6:O6) -> 0.040016637
A7: Pengadaan Air, Pengelolaan Sampah, Limbah dan Daur Ulang | C7: 0.0011222254 | D7: 0.0010922033 | E7: 0.0010887267 | F7: 0.0010849841 | G7: =AVERAGE(C7:F7) -> 0.0010970349 | H7: =C7*$C$20 -> 7.1195662 | I7: =D7*$D$20 -> 7.1130174 | J7: =E7*$E$20 -> 7.5392579 | K7: =F7*$F$20 -> 8.0892186 | L7: 0.0791 | M7: 0.0346 | N7: 0.0543 | O7: 0.054922875 | P7: =AVERAGE(L7:O7) -> 0.055730719
A8: Konstruksi | C8: 0.10896006 | D8: 0.1076713 | E8: 0.10348585 | F8: 0.10395893 | G8: =AVERAGE(C8:F8) -> 0.10601904 | H8: =C8*$C$20 -> 691.25895 | I8: =D8*$D$20 -> 701.21367 | J8: =E8*$E$20 -> 716.62295 | K8: =F8*$F$20 -> 775.07727 | L8: 0.0589 | M8: 0.0508 | N8: 0.0166 | O8: 0.063400918 | P8: =AVERAGE(L8:O8) -> 0.04742523
A9: Perdagangan Besar dan Eceran; Reparasi Mobil dan Sepeda Motor | C9: 0.19181227 | D9: 0.19457637 | E9: 0.19724608 | F9: 0.19936731 | G9: =AVERAGE(C9:F9) -> 0.1957505 | H9: =C9*$C$20 -> 1216.8858 | I9: =D9*$D$20 -> 1267.1864 | J9: =E9*$E$20 -> 1365.8975 | K9: =F9*$F$20 -> 1486.4049 | L9: 0.0985 | M9: 0.0784 | N9: 0.072 | O9: 0.069945725 | P9: =AVERAGE(L9:O9) -> 0.079711431
A10: Transportasi dan Pergudangan | C10: 0.0073756459 | D10: 0.0075535799 | E10: 0.0076849907 | F10: 0.0078885497 | G10: =AVERAGE(C10:F10) -> 0.0076256915 | H10: =C10*$C$20 -> 46.792204 | I10: =D10*$D$20 -> 49.192991 | J10: =E10*$E$20 -> 53.217331 | K10: =F10*$F$20 -> 58.81395 | L10: 0.0809 | M10: 0.0887 | N10: 0.0761 | O10: 0.086600741 | P10: =AVERAGE(L10:O10) -> 0.083075185
A11: Penyediaan Akomodasi dan Makan Minum | C11: 0.012827779 | D11: 0.013232595 | E11: 0.014112495 | F11: 0.014643303 | G11: =AVERAGE(C11:F11) -> 0.013704043 | H11: =C11*$C$20 -> 81.381352 | I11: =D11*$D$20 -> 86.177807 | J11: =E11*$E$20 -> 97.726773 | K11: =F11*$F$20 -> 109.17475 | L11: 0.0604 | M11: 0.0966 | N11: 0.128 | O11: 0.09837692 | P11: =AVERAGE(L11:O11) -> 0.09584423
A12: Informasi dan Komunikasi | C12: 0.076114932 | D12: 0.07647256 | E12: 0.077381142 | F12: 0.078249201 | G12: =AVERAGE(C12:F12) -> 0.077054459 | H12: =C12*$C$20 -> 482.88454 | I12: =D12*$D$20 -> 498.03061 | J12: =E12*$E$20 -> 535.85202 | K12: =F12*$F$20 -> 583.39552 | L12: 0.0781 | M12: 0.068 | N12: 0.0693 | O12: 0.07043661 | P12: =AVERAGE(L12:O12) -> 0.071459153
A13: Jasa Keuangan dan Asuransi | C13: 0.020174282 | D13: 0.020191093 | E13: 0.020454012 | F13: 0.02063996 | G13: =AVERAGE(C13:F13) -> 0.020364837 | H13: =C13*$C$20 -> 127.98867 | I13: =D13*$D$20 -> 131.4953 | J13: =E13*$E$20 -> 141.64076 | K13: =F13*$F$20 -> 153.88349 | L13: 0.1305 | M13: 0.0705 | N13: 0.0714 | O13: 0.068185073 | P13: =AVERAGE(L13:O13) -> 0.085146268
A14: Real Estate | C14: 0.02071999 | D14: 0.021065258 | E14: 0.021516074 | F14: 0.021534245 | G14: =AVERAGE(C14:F14) -> 0.021208892 | H14: =C14*$C$20 -> 131.45072 | I14: =D14*$D$20 -> 137.18833 | J14: =E14*$E$20 -> 148.99537 | K14: =F14*$F$20 -> 160.55093 | L14: 0.0909 | M14: 0.0807 | N14: 0.0803 | O14: 0.05945566 | P14: =AVERAGE(L14:O14) -> 0.077838915
... A19: Jasa Lainnya | C19: 0.019542412 | D19: 0.019732849 | E19: 0.019973101 | F19: 0.01950048 | G19: =AVERAGE(C19:F19) -> 0.019687211 | H19: =C19*$C$20 -> 123.97999 | I19: =D19*$D$20 -> 128.51097 | J19: =E19*$E$20 -> 138.31053 | K19: =F19*$F$20 -> 145.38797 | L19: 0.0427 | M19: 0.0734 | N19: 0.0706 | O19: 0.03351306 | P19: =AVERAGE(L19:O19) -> 0.055053265
A20: Total Pengeluaran Investasi | B20: =5003771.8/1000 -> 5003.7718 | C20: 6344.15 | D20: 6512.54 | E20: 6924.84 | F20: 7455.61 | G20: =5003771.8/1000 -> 5003.7718 | H20: =SUM(H3:H19) -> 6344.15 | I20: =SUM(I3:I19) -> 6512.54 | J20: =SUM(J3:J19) -> 6924.84 | K20: =SUM(K3:K19) -> 7455.61
B24: =ICOR!B3/$D$24 -> 0.3802797 | C24: PDRB 2012 | D24: =18562694.7/1000 -> 18562.695 | E24: =B24*$B$20 -> 1902.8328 | H24: PDRB 2013 | I24: =19848.84 -> 19848.84
B25: =ICOR!B4/$D$24 -> 0.0011120045 | E25: =B25*$B$20 -> 5.5642167
B26: =ICOR!B5/$D$24 -> 0.070951514 | E26: =B26*$B$20 -> 355.02519
B27: =ICOR!B6/$D$24 -> 0.18671843 | E27: =B27*$B$20 -> 934.29644
B28: =ICOR!B7/$D$24 -> 0.075492692 | E28: =B28*$B$20 -> 377.74821
B29: =ICOR!B8/$D$24 -> 0.020308792 | E29: =B29*$B$20 -> 101.62056
B30: =ICOR!B9/$D$24 -> 0.045892383 | E30: =B30*$B$20 -> 229.63501
B31: =ICOR!B10/$D$24 -> 0.025521607 | E31: =B31*$B$20 -> 127.7043
B32: =ICOR!B11/$D$24 -> 0.0080128129 | E32: =B32*$B$20 -> 40.094287
B33: =ICOR!B12/$D$24 -> 0.019954614 | E33: =B33*$B$20 -> 99.848333
A35: Sektor Ekonomi Non Potensial | B35: 2013 | C35: 2014 | D35: 2015 | E35: 2016 | F35: Rata-rata
A36: Pertambangan dan Penggalian | B36: 0.0165 | C36: 0.0608 | D36: 0.0964 | E36: 0.034175707 | F36: 0.051968927
A37: Industri Pengolahan | B37: 0.0694 | C37: 0.0847 | D37: 0.0814 | E37: 0.086458379 | F37: 0.080489595
A38: Pengadaan Listrik dan Gas | B38: 0.0378 | C38: 0.0283 | D38: 0.0045 | E38: 0.089466548 | F38: 0.040016637
A39: Perdagangan Besar dan Eceran; Reparasi Mobil dan Sepeda Motor | B39: 0.0985 | C39: 0.0784 | D39: 0.072 | E39: 0.069945725 | F39: 0.079711431
A40: Transportasi dan Pergudangan | B40: 0.0809 | C40: 0.0887 | D40: 0.0761 | E40: 0.086600741 | F40: 0.083075185
A41: Penyediaan Akomodasi dan Makan Minum | B41: 0.0604 | C41: 0.0966 | D41: 0.128 | E41: 0.09837692 | F41: 0.09584423
A42: Jasa Keuangan dan Asuransi | B42: 0.1305 | C42: 0.0705 | D42: 0.0714 | E42: 0.068185073 | F42: 0.085146268
A43: Jasa Perusahaan | B43: 0.0585 | C43: 0.0636 | D43: 0.0684 | E43: 0.057685087 | F43: 0.062046272
A44: Jasa Pendidikan | B44: 0.0874 | C44: 0.0799 | D44: 0.0796 | E44: 0.063999998 | F44: 0.077725

Sheet ICOR
A1: Sektor Potensial Lamongan | B1: 2012 | D1: 2013 | F1: 2014 | H1: 2015 | J1: 2016
B2: Output | C2: Investasi | D2: Output | E2: Investasi | F2: Output | G2: Investasi | H2: Output | I2: Investasi | J2: Output | K2: Investasi
A3: Pertanian, Kehutanan, dan Perikanan | B3: 7059.016 | C3: 1902.8328 | D3: 7478.6526 | E3: 2390.3512 | F3: 7851.0616 | G3: 2423.2467 | H3: 8212.4295 | I3: 2548.2848 | J3: 8567.515 | K3: 2703.8864
A4: Pengadaan Air, Pengelolaan Sampah, Limbah dan Daur Ulang | B4: 20.6418 | C4: 5.5642167 | D4: 22.27487 | E4: 7.1195662 | F4: 23.04542 | G4: 7.1130174 | H4: 24.29698 | I4: 7.5392579 | J4: 25.63144 | K4: 8.0892186
A5: Konstruksi | B5: 1317.0513 | C5: 355.02519 | D5: 2162.7305 | E5: 691.25895 | F5: 2271.8577 | G5: 701.21367 | H5: 2309.4811 | I5: 716.62295 | J5: 2455.9043 | K5: 775.07727
A6: Perdagangan Besar dan Eceran; Reparasi Mobil dan Sepeda Motor | B6: 3465.9973 | C6: 934.29644 | D6: 3807.2506 | E6: 1216.8858 | F6: 4105.5492 | G6: 1267.1864 | H6: 4401.9166 | I6: 1365.8975 | J6: 4709.8119 | K6: 1486.4049
A7: Informasi dan Komunikasi | B7: 1401.3478 | C7: 377.74821 | D7: 1510.793 | E7: 482.88454 | F7: 1613.5662 | G7: 498.03061 | H7: 1726.9055 | I7: 535.85202 | J7: 1848.5429 | K7: 583.39552
A8: Real Estate | B8: 376.9859 | C8: 101.62056 | D8: 411.26772 | E8: 131.45072 | F8: 444.47561 | G8: 137.18833 | H8: 480.17161 | I8: 148.99537 | J8: 508.72053 | K8: 160.55093
A9: Administrasi Pemerintahan, Pertahanan dan Jaminan Sosial Wajib | B9: 851.8863 | C9: 229.63501 | D9: 866.27512 | E9: 276.88166 | F9: 869.60703 | G9: 268.40604 | H9: 922.21229 | I9: 286.15887 | J9: 960.67937 | K9: 303.18801
A10: Jasa Pendidikan | B10: 473.7498 | C10: 127.7043 | D10: 515.17538 | E10: 164.66203 | F10: 556.36306 | G10: 171.72263 | H10: 600.6558 | I10: 186.38115 | J10: 639.09777 | K10: 201.69766
A11: Jasa Kesehatan dan Kegiatan Sosial | B11: 148.7394 | C11: 40.094287 | D11: 162.2789 | E11: 51.868108 | F11: 178.00013 | G11: 54.940115 | H11: 194.27051 | I11: 60.28138 | J11: 210.31577 | K11: 66.375133
A12: Jasa Lainnya | B12: 370.4114 | C12: 99.848333 | D12: 387.89417 | E12: 123.97999 | F12: 416.36187 | G12: 128.51097 | H12: 445.73727 | I12: 138.31053 | J12: 460.67529 | K12: 145.38797
A15: Sektor Potensial Lamongan | B15: Koefisien ICOR 2013 | C15: Koefisien ICOR 2014 | D15: Koefisien ICOR 2015 | E15: Koefisien ICOR 2016 | F15: Rata-rata Nilai ICOR
A16: Pertanian, Kehutanan, dan Perikanan | B16: =E3/(D3-B3) -> 5.6962409 | C16: =G3/(F3-D3) -> 6.5069492 | D16: =I3/(H3-F3) -> 7.0517752 | E16: =K3/(J3-H3) -> 7.6147478 | F16: =AVERAGE(B16:E16) -> 6.7174283
A17: Pengadaan Air, Pengelolaan Sampah, Limbah dan Daur Ulang | B17: =E4/(D4-B4) -> 4.359621 | C17: =G4/(F4-D4) -> 9.2310913 | D17: =I4/(H4-F4) -> 6.0238885 | E17: =K4/(J4-H4) -> 6.0617917 | F17: =AVERAGE(B17:E17) -> 6.4190981
A18: Konstruksi | B18: =E5/(D5-B5) -> 0.81740088 | C18: =G5/(F5-D5) -> 6.4256549 | D18: =I5/(H5-F5) -> 19.047292 | E18: =K5/(J5-H5) -> 5.2934041 | F18: =AVERAGE(B18:E18) -> 7.8959381
A19: Perdagangan Besar dan Eceran; Reparasi Mobil dan Sepeda Motor | B19: =E6/(D6-B6) -> 3.5659311 | C19: =G6/(F6-D6) -> 4.2480469 | D19: =I6/(H6-F6) -> 4.6087981 | E19: =K6/(J6-H6) -> 4.8276317 | F19: =AVERAGE(B19:E19) -> 4.312602
A20: Informasi dan Komunikasi | B20: =E7/(D7-B7) -> 4.4121146 | C20: =G7/(F7-D7) -> 4.8459162 | D20: =I7/(H7-F7) -> 4.7278576 | E20: =K7/(J7-H7) -> 4.7961866 | F20: =AVERAGE(B20:E20) -> 4.6955188
A21: Real Estate | B21: =E8/(D8-B8) -> 3.8344149 | C21: =G8/(F8-D8) -> 4.1311969 | D21: =I8/(H8-F8) -> 4.1740075 | E21: =K8/(J8-H8) -> 5.623713 | F21: =AVERAGE(B21:E21) -> 4.4408331
A22: Administrasi Pemerintahan, Pertahanan dan Jaminan Sosial Wajib | B22: =E9/(D9-B9) -> 19.242833 | C22: =G9/(F9-D9) -> 80.55621 | D22: =I9/(H9-F9) -> 5.4397387 | E22: =K9/(J9-H9) -> 7.8817528 | F22: =AVERAGE(B22:E22) -> 28.280134
A23: Jasa Pendidikan | B23: =E10/(D10-B10) -> 3.9748876 | C23: =G10/(F10-D10) -> 4.1692717 | D23: =I10/(H10-F10) -> 4.207939 | E23: =K10/(J10-H10) -> 5.2468087 | F23: =AVERAGE(B23:E23) -> 4.3997268
A24: Jasa Kesehatan dan Kegiatan Sosial | B24: =E11/(D11-B11) -> 3.8308733 | C24: =G11/(F11-D11) -> 3.4946448 | D24: =I11/(H11-F11) -> 3.7049768 | E24: =K11/(J11-H11) -> 4.136744 | F24: =AVERAGE(B24:E24) -> 3.7918097
A25: Jasa Lainnya | B25: =E12/(D12-B12) -> 7.0915532 | C25: =G12/(F12-D12) -> 4.5142729 | D25: =I12/(H12-F12) -> 4.7083795 | E25: =K12/(J12-H12) -> 9.7327473 | F25: =AVERAGE(B25:E25) -> 6.5117382
A27: Sektor Ekonomi | B27: 2013 | D27: 2014 | F27: 2015 | H27: 2016 | J27: ICOR 2014 | K27: ICOR 2015 | L27: ICOR 2016 | M27: Rata-rata
B28: PDRB | C28: Investasi | D28: PDRB | E28: Investasi | F28: PDRB | G28: Investasi | H28: PDRB | I28: Investasi
A29: Pertanian, Kehutanan, dan Perikanan | B29: 7478.6526 | C29: 2390.3512 | D29: 7851.0617 | E29: 2423.2467 | F29: 8212.4295 | G29: 2548.2848 | H29: 8567.515 | I29: 2703.8864 | J29: 6.5069492 | K29: 7.0517752 | L29: 7.6147478 | M29: =AVERAGE(J29:L29) -> 7.0578241
A30: Pertambangan dan Penggalian | B30: 244.44558 | C30: 78.130489 | D30: 259.31632 | E30: 80.038528 | F30: 284.31892 | G30: 88.223049 | H30: 294.03572 | I30: 92.79694 | J30: 5.3822828 | K30: 3.528555 | L30: 9.5501544 | M30: =AVERAGE(J30:L30) -> 6.1536641
A31: Industri Pengolahan | B31: 1408.4729 | C31: 450.18067 | D31: 1571.8029 | E31: 485.14026 | F31: 1693.0032 | G31: 525.33226 | H31: 1839.3775 | I31: 580.50295 | J31: 2.9703073 | K31: 4.3344135 | L31: 3.96588 | M31: =AVERAGE(J31:L31) -> 3.7568669
A32: Pengadaan Listrik dan Gas | B32: 14.98776 | C32: 4.7904365 | D32: 15.93118 | E32: 4.9171922 | F32: 16.18102 | G32: 5.0209072 | H32: 17.62868 | I32: 5.5635675 | J32: 5.2120924 | K32: 20.096491 | L32: 3.8431451 | M32: =AVERAGE(J32:L32) -> 9.7172428
A33: Pengadaan Air, Pengelolaan Sampah, Limbah dan Daur Ulang | B33: 22.27487 | C33: 7.1195662 | D33: 23.04542 | E33: 7.1130174 | F33: 24.29698 | G33: 7.5392579 | H33: 25.63144 | I33: 8.0892186 | J33: 9.2310913 | K33: 6.0238885 | L33: 6.0617917 | M33: =AVERAGE(J33:L33) -> 7.1055905
A34: Konstruksi | B34: 2162.7305 | C34: 691.25895 | D34: 2271.8577 | E34: 701.21367 | F34: 2309.4811 | G34: 716.62295 | H34: 2455.9043 | I34: 775.07727 | J34: 6.4256549 | K34: 19.047292 | L34: 5.2934041 | M34: =AVERAGE(J34:L34) -> 10.25545
A35: Perdagangan Besar dan Eceran; Reparasi Mobil dan Sepeda Motor | B35: 3807.2506 | C35: 1216.8858 | D35: 4105.5492 | E35: 1267.1864 | F35: 4401.9166 | G35: 1365.8975 | H35: 4709.8119 | I35: 1486.4049 | J35: 4.2480469 | K35: 4.6087981 | L35: 4.8276317 | M35: =AVERAGE(J35:L35) -> 4.5614923
A36: Transportasi dan Pergudangan | B36: 146.398 | C36: 46.792204 | D36: 159.38006 | E36: 49.192991 | F36: 171.505 | G36: 53.217331 | H36: 186.35746 | I36: 58.81395 | J36: 3.7893055 | K36: 4.3890799 | L36: 3.9598794 | M36: =AVERAGE(J36:L36) -> 4.0460883
A37: Penyediaan Akomodasi dan Makan Minum | B37: 254.6165 | C37: 81.381352 | D37: 279.20693 | E37: 86.177807 | F37: 314.94684 | G37: 97.726773 | H37: 345.93034 | I37: 109.17475 | J37: 3.5045262 | K37: 2.7343878 | L37: 3.5236417 | M37: =AVERAGE(J37:L37) -> 3.2541852
A38: Informasi dan Komunikasi | B38: 1510.793 | C38: 482.88454 | D38: 1613.5662 | E38: 498.03061 | F38: 1726.9055 | G38: 535.85202 | H38: 1848.5429 | I38: 583.39552 | J38: 4.8459162 | K38: 4.7278576 | L38: 4.7961866 | M38: =AVERAGE(J38:L38) -> 4.7899868
A39: Jasa Keuangan dan Asuransi | B39: 400.43605 | C39: 127.98867 | D39: 426.03079 | E39: 131.4953 | F39: 456.4697 | G39: 141.64076 | H39: 487.59412 | I39: 153.88349 | J39: 5.1375908 | K39: 4.6532797 | L39: 4.94414 | M39: =AVERAGE(J39:L39) -> 4.9116702
A40: Real Estate | B40: 411.26772 | C40: 131.45072 | D40: 444.47561 | E40: 137.18833 | F40: 480.17161 | G40: 148.99537 | H40: 508.72053 | I40: 160.55093 | J40: 4.1311969 | K40: 4.1740075 | L40: 5.623713 | M40: =AVERAGE(J40:L40) -> 4.6429725
... A45: Jasa Lainnya | B45: 387.89417 | C45: 123.97999 | D45: 416.36187 | E45: 128.51097 | F45: 445.73727 | G45: 138.31053 | H45: 460.67529 | I45: 145.38797 | J45: 4.5142729 | K45: 4.7083795 | L45: 9.7327473 | M45: =AVERAGE(J45:L45) -> 6.3184666
L46: Rata-rata Total | M46: =AVERAGE(M29:M45) -> 7.143982

Sheet Kebutuhan Investasi
A1: Sektor Potensial Lamongan | B1: PDRB 2016 | C1: Rata-rata Nilai ICOR | D1: PDRB 2017 (1%) | E1: Kebutuhan Investasi 2017 (1%)
A2: Pertanian, Kehutanan, dan Perikanan | B2: 8567.515 | C2: 6.7174283 | D2: =B2+(B2*1%) -> 8653.1901 | E2: =C2*(D2-B2) -> 575.51667
A3: Pengadaan Air, Pengelolaan Sampah, Limbah dan Daur Ulang | B3: 25.63144 | C3: 6.4190981 | D3: =B3+(B3*1%) -> 25.887754 | E3: =C3*(D3-B3) -> 1.6453073
A4: Konstruksi | B4: 2455.9043 | C4: 7.8959381 | D4: =B4+(B4*1%) -> 2480.4633 | E4: =C4*(D4-B4) -> 193.91668
A5: Perdagangan Besar dan Eceran; Reparasi Mobil dan Sepeda Motor | B5: 4709.8119 | C5: 4.312602 | D5: =B5+(B5*1%) -> 4756.91 | E5: =C5*(D5-B5) -> 203.11544
A6: Informasi dan Komunikasi | B6: 1848.5429 | C6: 4.6955188 | D6: =B6+(B6*1%) -> 1867.0283 | E6: =C6*(D6-B6) -> 86.798677
A7: Real Estate | B7: 508.72053 | C7: 4.4408331 | D7: =B7+(B7*1%) -> 513.80774 | E7: =C7*(D7-B7) -> 22.59143
A8: Administrasi Pemerintahan, Pertahanan dan Jaminan Sosial Wajib | B8: 960.67937 | C8: 28.280134 | D8: =B8+(B8*1%) -> 970.28616 | E8: =C8*(D8-B8) -> 271.68141
A9: Jasa Pendidikan | B9: 639.09777 | C9: 4.3997268 | D9: =B9+(B9*1%) -> 645.48875 | E9: =C9*(D9-B9) -> 28.118556
A10: Jasa Kesehatan dan Kegiatan Sosial | B10: 210.31577 | C10: 3.7918097 | D10: =B10+(B10*1%) -> 212.41893 | E10: =C10*(D10-B10) -> 7.9747738
A11: Jasa Lainnya | B11: 460.67529 | C11: 6.5117382 | D11: =B11+(B11*1%) -> 465.28204 | E11: =C11*(D11-B11) -> 29.997969
A14: Sektor Potensial Lamongan | B14: PDRB 2016 | C14: Rata-rata Nilai ICOR | D14: PDRB 2020 (6.5%) | E14: Kebutuhan Investasi 2020 (6.5%)
A15: Pertanian, Kehutanan, dan Perikanan | B15: 8567.515 | C15: 6.7174283 | D15: =B15+(B15*6.5%) -> 9124.4034 | E15: =C15*(D15-B15) -> 3740.8584
A16: Pengadaan Air, Pengelolaan Sampah, Limbah dan Daur Ulang | B16: 25.63144 | C16: 6.4190981 | D16: =B16+(B16*6.5%) -> 27.297484 | E16: =C16*(D16-B16) -> 10.694497
A17: Konstruksi | B17: 2455.9043 | C17: 7.8959381 | D17: =B17+(B17*6.5%) -> 2615.5381 | E17: =C17*(D17-B17) -> 1260.4584
A18: Perdagangan Besar dan Eceran; Reparasi Mobil dan Sepeda Motor | B18: 4709.8119 | C18: 4.312602 | D18: =B18+(B18*6.5%) -> 5015.9496 | E18: =C18*(D18-B18) -> 1320.2503
A19: Informasi dan Komunikasi | B19: 1848.5429 | C19: 4.6955188 | D19: =B19+(B19*6.5%) -> 1968.6982 | E19: =C19*(D19-B19) -> 564.1914
A20: Real Estate | B20: 508.72053 | C20: 4.4408331 | D20: =B20+(B20*6.5%) -> 541.78736 | E20: =C20*(D20-B20) -> 146.84429
A21: Administrasi Pemerintahan, Pertahanan dan Jaminan Sosial Wajib | B21: 960.67937 | C21: 28.280134 | D21: =B21+(B21*6.5%) -> 1023.1235 | E21: =C21*(D21-B21) -> 1765.9292
A22: Jasa Pendidikan | B22: 639.09777 | C22: 4.3997268 | D22: =B22+(B22*6.5%) -> 680.63913 | E22: =C22*(D22-B22) -> 182.77061
A23: Jasa Kesehatan dan Kegiatan Sosial | B23: 210.31577 | C23: 3.7918097 | D23: =B23+(B23*6.5%) -> 223.9863 | E23: =C23*(D23-B23) -> 51.83603
A24: Jasa Lainnya | B24: 460.67529 | C24: 6.5117382 | D24: =B24+(B24*6.5%) -> 490.61918 | E24: =C24*(D24-B24) -> 194.9868
B26: 2013 | C26: 2014 | D26: 2015 | E26: 2016 | F26: 2017 | G26: 2020 | H26: Rata-rata | I26: Kebutuhan Investasi 2020
A27: Nilai Icor Lamongan | B27: 4.93 | C27: 5.21 | D27: 5.69 | E27: 5.7 | F27: 6.11 | H27: =AVERAGE(B27:F27) -> 5.528 | I27: =H27*(G28-E28) -> 8488.5011
A28: PDRB Kabupaten Lamongan | B28: 19848.838 | C28: 21099.937 | D28: 22316.878 | E28: 23623.792 | F28: 24927.95 | G28: =E28+(E28*6.5%) -> 25159.339
A29: Perubahan PDRB | B29: 1286.14 | C29: 1251.1 | D29: 1216.94 | E29: 1306.91 | F29: 1304.16
A31: Sektor Ekonomi | B31: PDRB 2016 | C31: Rata-rata Pertumbuhan | D31: PDRB 2020 | F31: ICOR | G31: Investasi
A33: Pertanian, Kehutanan, dan Perikanan | B33: 8567.515 | C33: 0.057 | E33: =B33+(B33*C33) -> 9055.8633
A34: Pertambangan dan Penggalian | B34: 294.03572 | C34: 0.051968927 | D34: =B34+(B34*C34) -> 309.31644 | F34: 6.1536641 | G34: =F34*(D34-B34) -> 94.032422
A35: Industri Pengolahan | B35: 1839.3775 | C35: 0.080489595 | D35: =B35+(B35*C35) -> 1987.4282 | F35: 3.7568669 | G35: =F35*(D35-B35) -> 556.20696
A36: Pengadaan Listrik dan Gas | B36: 17.62868 | C36: 0.040016637 | D36: =B36+(B36*C36) -> 18.33412 | F36: 9.7172428 | G36: =F36*(D36-B36) -> 6.8549365
A37: Pengadaan Air, Pengelolaan Sampah, Limbah dan Daur Ulang | B37: 25.63144 | C37: 0.057 | E37: =B37+(B37*C37) -> 27.092432
A38: Konstruksi | B38: 2455.9043 | C38: 0.057 | E38: =B38+(B38*C38) -> 2595.8908
A39: Perdagangan Besar dan Eceran; Reparasi Mobil dan Sepeda Motor | B39: 4709.8119 | C39: 0.079711431 | D39: =B39+(B39*C39) -> 5085.2377 | F39: 4.5614923 | G39: =F39*(D39-B39) -> 1712.5021
A40: Transportasi dan Pergudangan | B40: 186.35746 | C40: 0.083075185 | D40: =B40+(B40*C40) -> 201.83914 | F40: 4.0460883 | G40: =F40*(D40-B40) -> 62.640246
A41: Penyediaan Akomodasi dan Makan Minum | B41: 345.93034 | C41: 0.09584423 | D41: =B41+(B41*C41) -> 379.08577 | F41: 3.2541852 | G41: =F41*(D41-B41) -> 107.8939
A42: Informasi dan Komunikasi | B42: 1848.5429 | C42: 0.057 | E42: =B42+(B42*C42) -> 1953.9098 | G42: =F42*(D42-B42) -> 0
A43: Jasa Keuangan dan Asuransi | B43: 487.59412 | C43: 0.085146268 | D43: =B43+(B43*C43) -> 529.11094 | F43: 4.9116702 | G43: =F43*(D43-B43) -> 203.91693
A44: Real Estate | B44: 508.72053 | C44: 0.057 | E44: =B44+(B44*C44) -> 537.7176
A45: Jasa Perusahaan | B45: 65.97444 | C45: 0.062046272 | D45: =B45+(B45*C45) -> 70.067908 | F45: 5.2634977 | G45: =F45*(D45-B45) -> 21.54596
...

Sheet Klasifikasi
A1: Kriteria | B1: LQ >1 | C1: LQ <= 1 | E1: Sektor Ekonomi | F1: LQ | G1: ICOR
A2: Nilai ICOR <=4 | B2: Sektor Potensial Efisien | C2: Sektor Non Potensial Efisien
A3: Nilai ICOR >4 | B3: Sektor Potensial Tidak Efisein | C3: Sektor Non Potensial Tidak Efisien | E3: Pertanian, Kehutanan, dan Perikanan | F3: 3.0355534 | G3: 6.7174283
E4: Pertambangan dan Penggalian | F4: 0.24875368 | G4: 6.1536641
E5: Industri Pengolahan | F5: 0.25510709 | G5: 3.7568669
E6: Pengadaan Listrik dan Gas | F6: 0.21647728 | G6: 9.7172428
E7: Pengadaan Air, Pengelolaan Sampah, Limbah dan Daur Ulang | F7: 1.1089967 | G7: 6.4190981
A8: Kriteria | B8: LQ >1 | C8: LQ <= 1 | E8: Konstruksi | F8: 1.1592587 | G8: 7.8959381
A9: Nilai ICOR <=4 | B9: Jasa Kesehatan dan Kegiatan Sosial | C9: Industri Pengolahan | E9: Perdagangan Besar dan Eceran; Reparasi Mobil dan Sepeda Motor | F9: 1.0702297 | G9: 4.312602
C10: Penyediaan Akomodasi dan Makan Minum | E10: Transportasi dan Pergudangan | F10: 0.26280698 | G10: 4.0460883
C11: Transportasi dan Pergudangan | E11: Penyediaan Akomodasi dan Makan Minum | F11: 0.2723354 | G11: 3.2541852
A12: Nilai ICOR >4 | B12: Pertanian, Kehutanan, dan Perikanan | C12: Pertambangan dan Penggalian | E12: Informasi dan Komunikasi | F12: 1.3933594 | G12: 4.6955188
B13: Pengadaan Air, Pengelolaan Samapah, Limbah dan Daur Ulang | C13: Pengadaan Listrik dan Gas | E13: Jasa Keuangan dan Asuransi | F13: 0.7861158 | G13: 4.9116702
B14: Konstruksi | C14: Perdagangan Besar dan Eceran;Reparasi Mobil dan Sepedah Motor | E14: Real Estate | F14: 1.2241937 | G14: 4.4408331
B15: Informasi dan Komunikasi | C15: Jasa Keuangan dan Asuransi | E15: Jasa Perusahaan | F15: 0.36019552 | G15: 5.2634977
B16: real estate | C16: Jasa Perusahaan | E16: Administrasi Pemerintahan, Pertahanan dan Jaminan Sosial Wajib | F16: 1.8144781 | G16: 28.280134
B17: Administrasi Pemerintahan, Pertahanan, dan Jaminan Sosial Wajib | C17: Jasa Pendidikan | E17: Jasa Pendidikan | F17: 1.0059436 | G17: 4.3997268
B18: Jasa Lainnya | E18: Jasa Kesehatan dan Kegiatan Sosial | F18: 1.3150217 | G18: 3.7918097
E19: Jasa Lainnya | F19: 1.3504831 | G19: 6.5117382

Sheet Sheet1
A1: Sektor Ekonomi | B1: Output 2020 | C1: Pertumbuhan Output | D1: Investasi 2020
A2: Pertanian, Kehutanan, dan Perikanan | B2: 9055.8633 | C2: 0.057 | D2: 3280.445
A3: Pertambangan dan Penggalian | B3: 309.31644 | C3: 0.051968927 | D3: 94.032422
A4: Industri Pengolahan | B4: 1987.4282 | C4: 0.080489595 | D4: 556.20696
A5: Pengadaan Listrik dan Gas | B5: 18.33412 | C5: 0.040016637 | D5: 6.8549365
A6: Pengadaan Air, Pengelolaan Sampah, Limbah dan Daur Ulang | B6: 27.092432 | C6: 0.057 | D6: 9.3782515
A7: Konstruksi | B7: 2595.8908 | C7: 0.057 | D7: 1105.3251
A8: Perdagangan Besar dan Eceran; Reparasi Mobil dan Sepeda Motor | B8: 5085.2377 | C8: 0.079711431 | D8: 1712.5021
A9: Transportasi dan Pergudangan | B9: 201.83914 | C9: 0.083075185 | D9: 62.640246
A10: Penyediaan Akomodasi dan Makan Minum | B10: 379.08577 | C10: 0.09584423 | D10: 107.8939
A11: Informasi dan Komunikasi | B11: 1953.9098 | C11: 0.057 | D11: 494.75246
A12: Jasa Keuangan dan Asuransi | B12: 529.11094 | C12: 0.085146268 | D12: 203.91693
A13: Real Estate | B13: 537.7176 | C13: 0.057 | D13: 128.77115
... A18: Jasa Lainnya | B18: 486.93378 | C18: 0.057 | D18: 170.98842
A19: TOTAL | B19: =SUM(B2:B18) -> 25164.342 | D19: =SUM(D2:D18) -> 9774.88
